Workbook

Sheet Planilha1
B1: GERAL | H1: VAREJO | N1: KEY | T1: POSITIVACAO PAO DA FAZENDA | Y1: PREMIAÇÃO POSITIVAÇÃO | AI1: PREMIAÇÃO FATURAMENTO
Y2: VENDEDOR | Z2: META A | AA2: META B | AB2: META C | AC2: META D | AD2: ATINGIDO | AE2: PREMIAÇÃO ATINGIDA | AF2: PRÓXIMA META | AG2: FALTA | AI2: VENDEDOR | AJ2: META A | AK2: META B | AL2: META C | AM2: META D | AN2: ATINGIDO | AO2: PREMIAÇÃO ATINGIDA | AP2: PRÓXIMA META | AQ2: FALTA
Y3: SJC | Z3: =_xlfn.XLOOKUP(Tabela17[[#This Row],[VENDEDOR]],[1]!Tabela4[VENDEDOR],[1]!Tabela4[META A]) -> 35 | AA3: =_xlfn.XLOOKUP(Tabela17[[#This Row],[VENDEDOR]],[1]!Tabela4[VENDEDOR],[1]!Tabela4[META B]) -> 30 | AB3: =_xlfn.XLOOKUP(Tabela17[[#This Row],[VENDEDOR]],[1]!Tabela4[VENDEDOR],[1]!Tabela4[META C]) -> 24.5 | AC3: =_xlfn.XLOOKUP(Tabela17[[#This Row],[VENDEDOR]],[1]!Tabela4[VENDEDOR],[1]!Tabela4[META D]) -> 14 | AD3: =IFERROR(_xlfn.XLOOKUP(Y3,'[1]BASE PYTHON'!$K:$K,'[1]BASE PYTHON'!$N:$N,0),0) -> 0 | AE3: {=_xlfn.IFS(AD3>=Z3,"A",AD3>=AA3,"B",AD3>=AB3,"C",AD3>=AC3,"D",TRUE,"NÃO ATINGIDO")} -> NÃO ATINGIDO | AF3: {=_xlfn.IFS(AE3="NÃO ATINGIDO","D",AE3="D","C",AE3="C","B",AE3="B","A",AE3="A","OBJETIVO ALCANÇADO")} -> D | AG3: {=_xlfn.IFS(AF3="D",MAX(AC3-AD3,0),AF3="C",MAX(AB3-AD3,0),AF3="B",MAX(AA3-AD3,0),AF3="A",MAX(Z3-AD3,0),AF3="OBJETIVO ALCANÇADO",0)} -> 14 | AI3: SJC | AJ3: =_xlfn.XLOOKUP(Tabela817[[#This Row],[VENDEDOR]],[1]!Tabela8[VENDEDOR],[1]!Tabela8[META A]) -> 88000 | AK3: =_xlfn.XLOOKUP(Tabela817[[#This Row],[VENDEDOR]],[1]!Tabela8[VENDEDOR],[1]!Tabela8[META B]) -> 74800 | AL3: =_xlfn.XLOOKUP(Tabela817[[#This Row],[VENDEDOR]],[1]!Tabela8[VENDEDOR],[1]!Tabela8[META C]) -> 61600 | AM3: =_xlfn.XLOOKUP(Tabela817[[#This Row],[VENDEDOR]],[1]!Tabela8[VENDEDOR],[1]!Tabela8[META D]) -> 39600 | AN3: =IFERROR(_xlfn.XLOOKUP(AI3,'[1]BASE PYTHON'!$E:$E,'[1]BASE PYTHON'!$F:$F,0),0) -> 59228.23 | AO3: {=_xlfn.IFS(AN3>=AJ3,"A",AN3>=AK3,"B",AN3>=AL3,"C",AN3>=AM3,"D",TRUE,"NÃO ATINGIDO")} -> D | AP3: {=_xlfn.IFS(AO3="NÃO ATINGIDO","D",AO3="D","C",AO3="C","B",AO3="B","A",AO3="A","OBJETIVO ALCANÇADO")} -> C | AQ3: {=_xlfn.IFS(AP3="D",MAX(AM3-AN3,0),AP3="C",MAX(AL3-AN3,0),AP3="B",MAX(AK3-AN3,0),AP3="A",MAX(AJ3-AN3,0),AP3="OBJETIVO ALCANÇADO",0)} -> 2371.77
B4: META MÊS | C4: =SUM(C10:C36) -> 6031000 | H4: META DIA | I4: =SUM(I10:I27) -> 300470 | N4: META SEMANAL | O4: =SUM(O11:O17) -> 0 | T4: META MÊS | U4: =SUM(U10:U26) -> 560 | Y4: VENDEDOR INTERNO 1 | Z4: =_xlfn.XLOOKUP(Tabela17[[#This Row],[VENDEDOR]],[1]!Tabela4[VENDEDOR],[1]!Tabela4[META A]) -> 79 | AA4: =_xlfn.XLOOKUP(Tabela17[[#This Row],[VENDEDOR]],[1]!Tabela4[VENDEDOR],[1]!Tabela4[META B]) -> 68 | AB4: =_xlfn.XLOOKUP(Tabela17[[#This Row],[VENDEDOR]],[1]!Tabela4[VENDEDOR],[1]!Tabela4[META C]) -> 56 | AC4: =_xlfn.XLOOKUP(Tabela17[[#This Row],[VENDEDOR]],[1]!Tabela4[VENDEDOR],[1]!Tabela4[META D]) -> 36 | AD4: =IFERROR(_xlfn.XLOOKUP(Y4,'[1]BASE PYTHON'!$K:$K,'[1]BASE PYTHON'!$M:$M,0),0) -> 68 | AE4: {=_xlfn.IFS(AD4>=Z4,"A",AD4>=AA4,"B",AD4>=AB4,"C",AD4>=AC4,"D",TRUE,"NÃO ATINGIDO")} -> B | AF4: {=_xlfn.IFS(AE4="NÃO ATINGIDO","D",AE4="D","C",AE4="C","B",AE4="B","A",AE4="A","OBJETIVO ALCANÇADO")} -> A | AG4: {=_xlfn.IFS(AF4="D",MAX(AC4-AD4,0),AF4="C",MAX(AB4-AD4,0),AF4="B",MAX(AA4-AD4,0),AF4="A",MAX(Z4-AD4,0),AF4="OBJETIVO ALCANÇADO",0)} -> 11 | AI4: VENDEDOR INTERNO 1 | AJ4: =_xlfn.XLOOKUP(Tabela817[[#This Row],[VENDEDOR]],[1]!Tabela8[VENDEDOR],[1]!Tabela8[META A]) -> 79000 | AK4: =_xlfn.XLOOKUP(Tabela817[[#This Row],[VENDEDOR]],[1]!Tabela8[VENDEDOR],[1]!Tabela8[META B]) -> 67150 | AL4: =_xlfn.XLOOKUP(Tabela817[[#This Row],[VENDEDOR]],[1]!Tabela8[VENDEDOR],[1]!Tabela8[META C]) -> 55300 | AM4: =_xlfn.XLOOKUP(Tabela817[[#This Row],[VENDEDOR]],[1]!Tabela8[VENDEDOR],[1]!Tabela8[META D]) -> 35550 | AN4: =IFERROR(_xlfn.XLOOKUP(AI4,'[1]BASE PYTHON'!$E:$E,'[1]BASE PYTHON'!$F:$F,0),0) -> 58769.76 | AO4: {=_xlfn.IFS(AN4>=AJ4,"A",AN4>=AK4,"B",AN4>=AL4,"C",AN4>=AM4,"D",TRUE,"NÃO ATINGIDO")} -> C | AP4: {=_xlfn.IFS(AO4="NÃO ATINGIDO","D",AO4="D","C",AO4="C","B",AO4="B","A",AO4="A","OBJETIVO ALCANÇADO")} -> B | AQ4: {=_xlfn.IFS(AP4="D",MAX(AM4-AN4,0),AP4="C",MAX(AL4-AN4,0),AP4="B",MAX(AK4-AN4,0),AP4="A",MAX(AJ4-AN4,0),AP4="OBJETIVO ALCANÇADO",0)} -> 8380.24
B5: ATINGIDO | C5: =SUM(D10:D36) -> 3960015.8 | H5: ATINGIDO | I5: =SUM(J10:J27) -> 2185106.6 | N5: ATINGIDO | O5: =SUM(P11:P17) -> 0 | T5: ATINGIDO | U5: =SUM(V10:V26) -> 0 | Y5: CENTRO | Z5: =_xlfn.XLOOKUP(Tabela17[[#This Row],[VENDEDOR]],[1]!Tabela4[VENDEDOR],[1]!Tabela4[META A]) -> 35 | AA5: =_xlfn.XLOOKUP(Tabela17[[#This Row],[VENDEDOR]],[1]!Tabela4[VENDEDOR],[1]!Tabela4[META B]) -> 30 | AB5: =_xlfn.XLOOKUP(Tabela17[[#This Row],[VENDEDOR]],[1]!Tabela4[VENDEDOR],[1]!Tabela4[META C]) -> 24.5 | AC5: =_xlfn.XLOOKUP(Tabela17[[#This Row],[VENDEDOR]],[1]!Tabela4[VENDEDOR],[1]!Tabela4[META D]) -> 14 | AD5: =IFERROR(_xlfn.XLOOKUP(Y5,'[1]BASE PYTHON'!$K:$K,'[1]BASE PYTHON'!$N:$N,0),0) -> 0 | AE5: {=_xlfn.IFS(AD5>=Z5,"A",AD5>=AA5,"B",AD5>=AB5,"C",AD5>=AC5,"D",TRUE,"NÃO ATINGIDO")} -> NÃO ATINGIDO | AF5: {=_xlfn.IFS(AE5="NÃO ATINGIDO","D",AE5="D","C",AE5="C","B",AE5="B","A",AE5="A","OBJETIVO ALCANÇADO")} -> D | AG5: {=_xlfn.IFS(AF5="D",MAX(AC5-AD5,0),AF5="C",MAX(AB5-AD5,0),AF5="B",MAX(AA5-AD5,0),AF5="A",MAX(Z5-AD5,0),AF5="OBJETIVO ALCANÇADO",0)} -> 14 | AI5: CENTRO | AJ5: =_xlfn.XLOOKUP(Tabela817[[#This Row],[VENDEDOR]],[1]!Tabela8[VENDEDOR],[1]!Tabela8[META A]) -> 345000 | AK5: =_xlfn.XLOOKUP(Tabela817[[#This Row],[VENDEDOR]],[1]!Tabela8[VENDEDOR],[1]!Tabela8[META B]) -> 293250 | AL5: =_xlfn.XLOOKUP(Tabela817[[#This Row],[VENDEDOR]],[1]!Tabela8[VENDEDOR],[1]!Tabela8[META C]) -> 241500 | AM5: =_xlfn.XLOOKUP(Tabela817[[#This Row],[VENDEDOR]],[1]!Tabela8[VENDEDOR],[1]!Tabela8[META D]) -> 155250 | AN5: =IFERROR(_xlfn.XLOOKUP(AI5,'[1]BASE PYTHON'!$E:$E,'[1]BASE PYTHON'!$F:$F,0),0) -> 272619.35 | AO5: {=_xlfn.IFS(AN5>=AJ5,"A",AN5>=AK5,"B",AN5>=AL5,"C",AN5>=AM5,"D",TRUE,"NÃO ATINGIDO")} -> C | AP5: {=_xlfn.IFS(AO5="NÃO ATINGIDO","D",AO5="D","C",AO5="C","B",AO5="B","A",AO5="A","OBJETIVO ALCANÇADO")} -> B | AQ5: {=_xlfn.IFS(AP5="D",MAX(AM5-AN5,0),AP5="C",MAX(AL5-AN5,0),AP5="B",MAX(AK5-AN5,0),AP5="A",MAX(AJ5-AN5,0),AP5="OBJETIVO ALCANÇADO",0)} -> 20630.65
B6: FALTA | C6: =C4-C5 -> 2070984.2 | H6: FALTA | I6: =I4-I5 -> -1884636.6 | N6: FALTA | O6: =O4-O5 -> 0 | T6: FALTA | U6: =U4-U5 -> 560 | Y6: OSASCO | Z6: =_xlfn.XLOOKUP(Tabela17[[#This Row],[VENDEDOR]],[1]!Tabela4[VENDEDOR],[1]!Tabela4[META A]) -> 35 | AA6: =_xlfn.XLOOKUP(Tabela17[[#This Row],[VENDEDOR]],[1]!Tabela4[VENDEDOR],[1]!Tabela4[META B]) -> 30 | AB6: =_xlfn.XLOOKUP(Tabela17[[#This Row],[VENDEDOR]],[1]!Tabela4[VENDEDOR],[1]!Tabela4[META C]) -> 24.5 | AC6: =_xlfn.XLOOKUP(Tabela17[[#This Row],[VENDEDOR]],[1]!Tabela4[VENDEDOR],[1]!Tabela4[META D]) -> 14 | AD6: =IFERROR(_xlfn.XLOOKUP(Y6,'[1]BASE PYTHON'!$K:$K,'[1]BASE PYTHON'!$N:$N,0),0) -> 0 | AE6: {=_xlfn.IFS(AD6>=Z6,"A",AD6>=AA6,"B",AD6>=AB6,"C",AD6>=AC6,"D",TRUE,"NÃO ATINGIDO")} -> NÃO ATINGIDO | AF6: {=_xlfn.IFS(AE6="NÃO ATINGIDO","D",AE6="D","C",AE6="C","B",AE6="B","A",AE6="A","OBJETIVO ALCANÇADO")} -> D | AG6: {=_xlfn.IFS(AF6="D",MAX(AC6-AD6,0),AF6="C",MAX(AB6-AD6,0),AF6="B",MAX(AA6-AD6,0),AF6="A",MAX(Z6-AD6,0),AF6="OBJETIVO ALCANÇADO",0)} -> 14 | AI6: OSASCO | AJ6: =_xlfn.XLOOKUP(Tabela817[[#This Row],[VENDEDOR]],[1]!Tabela8[VENDEDOR],[1]!Tabela8[META A]) -> 331500 | AK6: =_xlfn.XLOOKUP(Tabela817[[#This Row],[VENDEDOR]],[1]!Tabela8[VENDEDOR],[1]!Tabela8[META B]) -> 281775 | AL6: =_xlfn.XLOOKUP(Tabela817[[#This Row],[VENDEDOR]],[1]!Tabela8[VENDEDOR],[1]!Tabela8[META C]) -> 232050 | AM6: =_xlfn.XLOOKUP(Tabela817[[#This Row],[VENDEDOR]],[1]!Tabela8[VENDEDOR],[1]!Tabela8[META D]) -> 149175 | AN6: =IFERROR(_xlfn.XLOOKUP(AI6,'[1]BASE PYTHON'!$E:$E,'[1]BASE PYTHON'!$F:$F,0),0) -> 251412.52 | AO6: {=_xlfn.IFS(AN6>=AJ6,"A",AN6>=AK6,"B",AN6>=AL6,"C",AN6>=AM6,"D",TRUE,"NÃO ATINGIDO")} -> C | AP6: {=_xlfn.IFS(AO6="NÃO ATINGIDO","D",AO6="D","C",AO6="C","B",AO6="B","A",AO6="A","OBJETIVO ALCANÇADO")} -> B | AQ6: {=_xlfn.IFS(AP6="D",MAX(AM6-AN6,0),AP6="C",MAX(AL6-AN6,0),AP6="B",MAX(AK6-AN6,0),AP6="A",MAX(AJ6-AN6,0),AP6="OBJETIVO ALCANÇADO",0)} -> 30362.485
B7: REALIZADO | C7: =1-(C6/C4) -> 0.65661016 | H7: REALIZADO | I7: =1-(I6/I4) -> 7.2722954 | N7: REALIZADO | O7: =IFERROR(1-(O6/O4),0) -> 0 | T7: REALIZADO | U7: =1-(U6/U4) -> 0 | Y7: INTERLAGOS | Z7: =_xlfn.XLOOKUP(Tabela17[[#This Row],[VENDEDOR]],[1]!Tabela4[VENDEDOR],[1]!Tabela4[META A]) -> 35 | AA7: =_xlfn.XLOOKUP(Tabela17[[#This Row],[VENDEDOR]],[1]!Tabela4[VENDEDOR],[1]!Tabela4[META B]) -> 30 | AB7: =_xlfn.XLOOKUP(Tabela17[[#This Row],[VENDEDOR]],[1]!Tabela4[VENDEDOR],[1]!Tabela4[META C]) -> 24.5 | AC7: =_xlfn.XLOOKUP(Tabela17[[#This Row],[VENDEDOR]],[1]!Tabela4[VENDEDOR],[1]!Tabela4[META D]) -> 14 | AD7: =IFERROR(_xlfn.XLOOKUP(Y7,'[1]BASE PYTHON'!$K:$K,'[1]BASE PYTHON'!$N:$N,0),0) -> 0 | AE7: {=_xlfn.IFS(AD7>=Z7,"A",AD7>=AA7,"B",AD7>=AB7,"C",AD7>=AC7,"D",TRUE,"NÃO ATINGIDO")} -> NÃO ATINGIDO | AF7: {=_xlfn.IFS(AE7="NÃO ATINGIDO","D",AE7="D","C",AE7="C","B",AE7="B","A",AE7="A","OBJETIVO ALCANÇADO")} -> D | AG7: {=_xlfn.IFS(AF7="D",MAX(AC7-AD7,0),AF7="C",MAX(AB7-AD7,0),AF7="B",MAX(AA7-AD7,0),AF7="A",MAX(Z7-AD7,0),AF7="OBJETIVO ALCANÇADO",0)} -> 14 | AI7: INTERLAGOS | AJ7: =_xlfn.XLOOKUP(Tabela817[[#This Row],[VENDEDOR]],[1]!Tabela8[VENDEDOR],[1]!Tabela8[META A]) -> 281000 | AK7: =_xlfn.XLOOKUP(Tabela817[[#This Row],[VENDEDOR]],[1]!Tabela8[VENDEDOR],[1]!Tabela8[META B]) -> 238850 | AL7: =_xlfn.XLOOKUP(Tabela817[[#This Row],[VENDEDOR]],[1]!Tabela8[VENDEDOR],[1]!Tabela8[META C]) -> 196700 | AM7: =_xlfn.XLOOKUP(Tabela817[[#This Row],[VENDEDOR]],[1]!Tabela8[VENDEDOR],[1]!Tabela8[META D]) -> 126450 | AN7: =IFERROR(_xlfn.XLOOKUP(AI7,'[1]BASE PYTHON'!$E:$E,'[1]BASE PYTHON'!$F:$F,0),0) -> 203747.15 | AO7: {=_xlfn.IFS(AN7>=AJ7,"A",AN7>=AK7,"B",AN7>=AL7,"C",AN7>=AM7,"D",TRUE,"NÃO ATINGIDO")} -> C | AP7: {=_xlfn.IFS(AO7="NÃO ATINGIDO","D",AO7="D","C",AO7="C","B",AO7="B","A",AO7="A","OBJETIVO ALCANÇADO")} -> B | AQ7: {=_xlfn.IFS(AP7="D",MAX(AM7-AN7,0),AP7="C",MAX(AL7-AN7,0),AP7="B",MAX(AK7-AN7,0),AP7="A",MAX(AJ7-AN7,0),AP7="OBJETIVO ALCANÇADO",0)} -> 35102.85
Y8: LESTE MOOCA | Z8: =_xlfn.XLOOKUP(Tabela17[[#This Row],[VENDEDOR]],[1]!Tabela4[VENDEDOR],[1]!Tabela4[META A]) -> 35 | AA8: =_xlfn.XLOOKUP(Tabela17[[#This Row],[VENDEDOR]],[1]!Tabela4[VENDEDOR],[1]!Tabela4[META B]) -> 30 | AB8: =_xlfn.XLOOKUP(Tabela17[[#This Row],[VENDEDOR]],[1]!Tabela4[VENDEDOR],[1]!Tabela4[META C]) -> 24.5 | AC8: =_xlfn.XLOOKUP(Tabela17[[#This Row],[VENDEDOR]],[1]!Tabela4[VENDEDOR],[1]!Tabela4[META D]) -> 14 | AD8: =IFERROR(_xlfn.XLOOKUP(Y8,'[1]BASE PYTHON'!$K:$K,'[1]BASE PYTHON'!$N:$N,0),0) -> 0 | AE8: {=_xlfn.IFS(AD8>=Z8,"A",AD8>=AA8,"B",AD8>=AB8,"C",AD8>=AC8,"D",TRUE,"NÃO ATINGIDO")} -> NÃO ATINGIDO | AF8: {=_xlfn.IFS(AE8="NÃO ATINGIDO","D",AE8="D","C",AE8="C","B",AE8="B","A",AE8="A","OBJETIVO ALCANÇADO")} -> D | AG8: {=_xlfn.IFS(AF8="D",MAX(AC8-AD8,0),AF8="C",MAX(AB8-AD8,0),AF8="B",MAX(AA8-AD8,0),AF8="A",MAX(Z8-AD8,0),AF8="OBJETIVO ALCANÇADO",0)} -> 14 | AI8: LESTE MOOCA | AJ8: =_xlfn.XLOOKUP(Tabela817[[#This Row],[VENDEDOR]],[1]!Tabela8[VENDEDOR],[1]!Tabela8[META A]) -> 206000 | AK8: =_xlfn.XLOOKUP(Tabela817[[#This Row],[VENDEDOR]],[1]!Tabela8[VENDEDOR],[1]!Tabela8[META B]) -> 175100 | AL8: =_xlfn.XLOOKUP(Tabela817[[#This Row],[VENDEDOR]],[1]!Tabela8[VENDEDOR],[1]!Tabela8[META C]) -> 144200 | AM8: =_xlfn.XLOOKUP(Tabela817[[#This Row],[VENDEDOR]],[1]!Tabela8[VENDEDOR],[1]!Tabela8[META D]) -> 92700 | AN8: =IFERROR(_xlfn.XLOOKUP(AI8,'[1]BASE PYTHON'!$E:$E,'[1]BASE PYTHON'!$F:$F,0),0) -> 148229.43 | AO8: {=_xlfn.IFS(AN8>=AJ8,"A",AN8>=AK8,"B",AN8>=AL8,"C",AN8>=AM8,"D",TRUE,"NÃO ATINGIDO")} -> C | AP8: {=_xlfn.IFS(AO8="NÃO ATINGIDO","D",AO8="D","C",AO8="C","B",AO8="B","A",AO8="A","OBJETIVO ALCANÇADO")} -> B | AQ8: {=_xlfn.IFS(AP8="D",MAX(AM8-AN8,0),AP8="C",MAX(AL8-AN8,0),AP8="B",MAX(AK8-AN8,0),AP8="A",MAX(AJ8-AN8,0),AP8="OBJETIVO ALCANÇADO",0)} -> 26870.565
A9: REFERENCIA | B9: VENDEDOR | C9: META A | D9: ATINGIDO | E9: FALTA | G9: REFERENCIA | H9: VENDEDOR | I9: COMPROMISSO | J9: ATINGIDO | K9: FALTA | O9: SEMANA 5 | S9: REFERENCIA | T9: VENDEDOR | U9: META A | V9: ATINGIDO | W9: FALTA | Y9: SANTO ANDRE | Z9: =_xlfn.XLOOKUP(Tabela17[[#This Row],[VENDEDOR]],[1]!Tabela4[VENDEDOR],[1]!Tabela4[META A]) -> 35 | AA9: =_xlfn.XLOOKUP(Tabela17[[#This Row],[VENDEDOR]],[1]!Tabela4[VENDEDOR],[1]!Tabela4[META B]) -> 30 | AB9: =_xlfn.XLOOKUP(Tabela17[[#This Row],[VENDEDOR]],[1]!Tabela4[VENDEDOR],[1]!Tabela4[META C]) -> 24.5 | AC9: =_xlfn.XLOOKUP(Tabela17[[#This Row],[VENDEDOR]],[1]!Tabela4[VENDEDOR],[1]!Tabela4[META D]) -> 14 | AD9: =IFERROR(_xlfn.XLOOKUP(Y9,'[1]BASE PYTHON'!$K:$K,'[1]BASE PYTHON'!$N:$N,0),0) -> 0 | AE9: {=_xlfn.IFS(AD9>=Z9,"A",AD9>=AA9,"B",AD9>=AB9,"C",AD9>=AC9,"D",TRUE,"NÃO ATINGIDO")} -> NÃO ATINGIDO | AF9: {=_xlfn.IFS(AE9="NÃO ATINGIDO","D",AE9="D","C",AE9="C","B",AE9="B","A",AE9="A","OBJETIVO ALCANÇADO")} -> D | AG9: {=_xlfn.IFS(AF9="D",MAX(AC9-AD9,0),AF9="C",MAX(AB9-AD9,0),AF9="B",MAX(AA9-AD9,0),AF9="A",MAX(Z9-AD9,0),AF9="OBJETIVO ALCANÇADO",0)} -> 14 | AI9: SANTO ANDRE | AJ9: =_xlfn.XLOOKUP(Tabela817[[#This Row],[VENDEDOR]],[1]!Tabela8[VENDEDOR],[1]!Tabela8[META A]) -> 175000 | AK9: =_xlfn.XLOOKUP(Tabela817[[#This Row],[VENDEDOR]],[1]!Tabela8[VENDEDOR],[1]!Tabela8[META B]) -> 148750 | AL9: =_xlfn.XLOOKUP(Tabela817[[#This Row],[VENDEDOR]],[1]!Tabela8[VENDEDOR],[1]!Tabela8[META C]) -> 122500 | AM9: =_xlfn.XLOOKUP(Tabela817[[#This Row],[VENDEDOR]],[1]!Tabela8[VENDEDOR],[1]!Tabela8[META D]) -> 78750 | AN9: =IFERROR(_xlfn.XLOOKUP(AI9,'[1]BASE PYTHON'!$E:$E,'[1]BASE PYTHON'!$F:$F,0),0) -> 135944.55 | AO9: {=_xlfn.IFS(AN9>=AJ9,"A",AN9>=AK9,"B",AN9>=AL9,"C",AN9>=AM9,"D",TRUE,"NÃO ATINGIDO")} -> C | AP9: {=_xlfn.IFS(AO9="NÃO ATINGIDO","D",AO9="D","C",AO9="C","B",AO9="B","A",AO9="A","OBJETIVO ALCANÇADO")} -> B | AQ9: {=_xlfn.IFS(AP9="D",MAX(AM9-AN9,0),AP9="C",MAX(AL9-AN9,0),AP9="B",MAX(AK9-AN9,0),AP9="A",MAX(AJ9-AN9,0),AP9="OBJETIVO ALCANÇADO",0)} -> 12805.45
A10: CAMPINAS | B10: CAMPINAS | C10: =_xlfn.XLOOKUP(Tabela13[[#This Row],[REFERENCIA]],[1]!Tabela2[VENDEDOR],[1]!Tabela2[META A],0) -> 70500 | D10: =_xlfn.XLOOKUP(Tabela13[[#This Row],[REFERENCIA]],'[1]BASE PYTHON'!$E:$E,'[1]BASE PYTHON'!$F:$F,0) -> 48786.56 | E10: =Tabela13[[#This Row],[META A]]-Tabela13[[#This Row],[ATINGIDO]] -> 21713.44 | G10: OSASCO | H10: OSASCO | I10: =_xlfn.XLOOKUP(Tabela5[[#This Row],[REFERENCIA]],'[1]BASE PYTHON'!$A$39:$A$55,'[1]BASE PYTHON'!$B$39:$B$55,0) -> 28040 | J10: =_xlfn.XLOOKUP(Tabela5[[#This Row],[REFERENCIA]],'[1]BASE PYTHON'!$H:$H,'[1]BASE PYTHON'!$I:$I,0) -> 251412.52 | K10: =Tabela5[[#This Row],[COMPROMISSO]]-Tabela5[[#This Row],[ATINGIDO]] -> -223372.52 | M10: REFERENCIA | N10: VENDEDOR | O10: COMPROMISSO | P10: ATINGIDO | Q10: FALTA | S10: CAMPINAS | T10: CAMPINAS | U10: =_xlfn.XLOOKUP(Tabela2[[#This Row],[REFERENCIA]],'[1]BASE PYTHON'!$A$63:$A$79,'[1]BASE PYTHON'!$B$63:$B$79) -> 35 | V10: =IFERROR(VLOOKUP(Tabela2[[#This Row],[REFERENCIA]],'[1]BASE PYTHON'!$K:$N,'[1]BASE PYTHON'!L$1,0),0) -> 0 | W10: =U10-V10 -> 35 | Y10: NORTE | Z10: =_xlfn.XLOOKUP(Tabela17[[#This Row],[VENDEDOR]],[1]!Tabela4[VENDEDOR],[1]!Tabela4[META A]) -> 35 | AA10: =_xlfn.XLOOKUP(Tabela17[[#This Row],[VENDEDOR]],[1]!Tabela4[VENDEDOR],[1]!Tabela4[META B]) -> 30 | AB10: =_xlfn.XLOOKUP(Tabela17[[#This Row],[VENDEDOR]],[1]!Tabela4[VENDEDOR],[1]!Tabela4[META C]) -> 24.5 | AC10: =_xlfn.XLOOKUP(Tabela17[[#This Row],[VENDEDOR]],[1]!Tabela4[VENDEDOR],[1]!Tabela4[META D]) -> 14 | AD10: =IFERROR(_xlfn.XLOOKUP(Y10,'[1]BASE PYTHON'!$K:$K,'[1]BASE PYTHON'!$N:$N,0),0) -> 0 | AE10: {=_xlfn.IFS(AD10>=Z10,"A",AD10>=AA10,"B",AD10>=AB10,"C",AD10>=AC10,"D",TRUE,"NÃO ATINGIDO")} -> NÃO ATINGIDO | AF10: {=_xlfn.IFS(AE10="NÃO ATINGIDO","D",AE10="D","C",AE10="C","B",AE10="B","A",AE10="A","OBJETIVO ALCANÇADO")} -> D | AG10: {=_xlfn.IFS(AF10="D",MAX(AC10-AD10,0),AF10="C",MAX(AB10-AD10,0),AF10="B",MAX(AA10-AD10,0),AF10="A",MAX(Z10-AD10,0),AF10="OBJETIVO ALCANÇADO",0)} -> 14 | AI10: NORTE | AJ10: =_xlfn.XLOOKUP(Tabela817[[#This Row],[VENDEDOR]],[1]!Tabela8[VENDEDOR],[1]!Tabela8[META A]) -> 272000 | AK10: =_xlfn.XLOOKUP(Tabela817[[#This Row],[VENDEDOR]],[1]!Tabela8[VENDEDOR],[1]!Tabela8[META B]) -> 231200 | AL10: =_xlfn.XLOOKUP(Tabela817[[#This Row],[VENDEDOR]],[1]!Tabela8[VENDEDOR],[1]!Tabela8[META C]) -> 190400 | AM10: =_xlfn.XLOOKUP(Tabela817[[#This Row],[VENDEDOR]],[1]!Tabela8[VENDEDOR],[1]!Tabela8[META D]) -> 122400 | AN10: =IFERROR(_xlfn.XLOOKUP(AI10,'[1]BASE PYTHON'!$E:$E,'[1]BASE PYTHON'!$F:$F,0),0) -> 211937.02 | AO10: {=_xlfn.IFS(AN10>=AJ10,"A",AN10>=AK10,"B",AN10>=AL10,"C",AN10>=AM10,"D",TRUE,"NÃO ATINGIDO")} -> C | AP10: {=_xlfn.IFS(AO10="NÃO ATINGIDO","D",AO10="D","C",AO10="C","B",AO10="B","A",AO10="A","OBJETIVO ALCANÇADO")} -> B | AQ10: {=_xlfn.IFS(AP10="D",MAX(AM10-AN10,0),AP10="C",MAX(AL10-AN10,0),AP10="B",MAX(AK10-AN10,0),AP10="A",MAX(AJ10-AN10,0),AP10="OBJETIVO ALCANÇADO",0)} -> 19262.98
A11: CENTRO | B11: CENTRO | C11: =_xlfn.XLOOKUP(Tabela13[[#This Row],[REFERENCIA]],[1]!Tabela2[VENDEDOR],[1]!Tabela2[META A],0) -> 345000 | D11: =_xlfn.XLOOKUP(Tabela13[[#This Row],[REFERENCIA]],'[1]BASE PYTHON'!$E:$E,'[1]BASE PYTHON'!$F:$F,0) -> 272619.35 | E11: =Tabela13[[#This Row],[META A]]-Tabela13[[#This Row],[ATINGIDO]] -> 72380.65 | G11: NORTE | H11: NORTE | I11: =_xlfn.XLOOKUP(Tabela5[[#This Row],[REFERENCIA]],'[1]BASE PYTHON'!$A$39:$A$55,'[1]BASE PYTHON'!$B$39:$B$55,0) -> 25000 | J11: =_xlfn.XLOOKUP(Tabela5[[#This Row],[REFERENCIA]],'[1]BASE PYTHON'!$H:$H,'[1]BASE PYTHON'!$I:$I,0) -> 211937.02 | K11: =Tabela5[[#This Row],[COMPROMISSO]]-Tabela5[[#This Row],[ATINGIDO]] -> -186937.02 | M11: KEY ABC | N11: KEY ABC | O11: {=IFERROR(_xlfn.XLOOKUP(M11,[1]!Tabela3[[#All],[VENDEDOR]],INDEX([1]!Tabela3[#All],0,MATCH($O$9,[1]!Tabela3[#Headers],0))),0)} -> 0 | P11: =IFERROR(GETPIVOTDATA("[Measures].[Soma de TOTAL 3]",'[1]BASE PYTHON'!$P$32,"[Intervalo 2].[REGIAO]","[Intervalo 2].[REGIAO].&["&N11&"]","[Intervalo 2].[SEMANA]","[Intervalo 2].[SEMANA].&["&RIGHT($O$9,1)&"]"),0) -> 0 | Q11: =Tabela8[[#This Row],[COMPROMISSO]]-Tabela8[[#This Row],[ATINGIDO]] -> 0 | S11: CENTRO | T11: CENTRO | U11: =_xlfn.XLOOKUP(Tabela2[[#This Row],[REFERENCIA]],'[1]BASE PYTHON'!$A$63:$A$79,'[1]BASE PYTHON'!$B$63:$B$79) -> 35 | V11: =IFERROR(VLOOKUP(Tabela2[[#This Row],[REFERENCIA]],'[1]BASE PYTHON'!$K:$N,'[1]BASE PYTHON'!L$1,0),0) -> 0 | W11: =U11-V11 -> 35 | Y11: LESTE | Z11: =_xlfn.XLOOKUP(Tabela17[[#This Row],[VENDEDOR]],[1]!Tabela4[VENDEDOR],[1]!Tabela4[META A]) -> 0 | AA11: =_xlfn.XLOOKUP(Tabela17[[#This Row],[VENDEDOR]],[1]!Tabela4[VENDEDOR],[1]!Tabela4[META B]) -> 0 | AB11: =_xlfn.XLOOKUP(Tabela17[[#This Row],[VENDEDOR]],[1]!Tabela4[VENDEDOR],[1]!Tabela4[META C]) -> 0 | AC11: =_xlfn.XLOOKUP(Tabela17[[#This Row],[VENDEDOR]],[1]!Tabela4[VENDEDOR],[1]!Tabela4[META D]) -> 0 | AD11: =IFERROR(_xlfn.XLOOKUP(Y11,'[1]BASE PYTHON'!$K:$K,'[1]BASE PYTHON'!$N:$N,0),0) -> 0 | AE11: {=_xlfn.IFS(AD11>=Z11,"A",AD11>=AA11,"B",AD11>=AB11,"C",AD11>=AC11,"D",TRUE,"NÃO ATINGIDO")} -> A | AF11: {=_xlfn.IFS(AE11="NÃO ATINGIDO","D",AE11="D","C",AE11="C","B",AE11="B","A",AE11="A","OBJETIVO ALCANÇADO")} -> OBJETIVO ALCANÇADO | AG11: {=_xlfn.IFS(AF11="D",MAX(AC11-AD11,0),AF11="C",MAX(AB11-AD11,0),AF11="B",MAX(AA11-AD11,0),AF11="A",MAX(Z11-AD11,0),AF11="OBJETIVO ALCANÇADO",0)} -> 0 | AI11: LESTE | AJ11: =_xlfn.XLOOKUP(Tabela817[[#This Row],[VENDEDOR]],[1]!Tabela8[VENDEDOR],[1]!Tabela8[META A]) -> 0 | AK11: =_xlfn.XLOOKUP(Tabela817[[#This Row],[VENDEDOR]],[1]!Tabela8[VENDEDOR],[1]!Tabela8[META B]) -> 0 | AL11: =_xlfn.XLOOKUP(Tabela817[[#This Row],[VENDEDOR]],[1]!Tabela8[VENDEDOR],[1]!Tabela8[META C]) -> 0 | AM11: =_xlfn.XLOOKUP(Tabela817[[#This Row],[VENDEDOR]],[1]!Tabela8[VENDEDOR],[1]!Tabela8[META D]) -> 0 | AN11: =IFERROR(_xlfn.XLOOKUP(AI11,'[1]BASE PYTHON'!$E:$E,'[1]BASE PYTHON'!$F:$F,0),0) -> 0 | AO11: {=_xlfn.IFS(AN11>=AJ11,"A",AN11>=AK11,"B",AN11>=AL11,"C",AN11>=AM11,"D",TRUE,"NÃO ATINGIDO")} -> A | AP11: {=_xlfn.IFS(AO11="NÃO ATINGIDO","D",AO11="D","C",AO11="C","B",AO11="B","A",AO11="A","OBJETIVO ALCANÇADO")} -> OBJETIVO ALCANÇADO | AQ11: {=_xlfn.IFS(AP11="D",MAX(AM11-AN11,0),AP11="C",MAX(AL11-AN11,0),AP11="B",MAX(AK11-AN11,0),AP11="A",MAX(AJ11-AN11,0),AP11="OBJETIVO ALCANÇADO",0)} -> 0
A12: IATAGAM JUNIOR | B12: IATAGAM JUNIOR | C12: =_xlfn.XLOOKUP(Tabela13[[#This Row],[REFERENCIA]],[1]!Tabela2[VENDEDOR],[1]!Tabela2[META A],0) -> 0 | D12: =_xlfn.XLOOKUP(Tabela13[[#This Row],[REFERENCIA]],'[1]BASE PYTHON'!$E:$E,'[1]BASE PYTHON'!$F:$F,0) -> 0 | E12: =Tabela13[[#This Row],[META A]]-Tabela13[[#This Row],[ATINGIDO]] -> 0 | G12: PIRITUBA | H12: PIRITUBA | I12: =_xlfn.XLOOKUP(Tabela5[[#This Row],[REFERENCIA]],'[1]BASE PYTHON'!$A$39:$A$55,'[1]BASE PYTHON'!$B$39:$B$55,0) -> 14810 | J12: =_xlfn.XLOOKUP(Tabela5[[#This Row],[REFERENCIA]],'[1]BASE PYTHON'!$H:$H,'[1]BASE PYTHON'!$I:$I,0) -> 107918.31 | K12: =Tabela5[[#This Row],[COMPROMISSO]]-Tabela5[[#This Row],[ATINGIDO]] -> -93108.31 | M12: PIRACICABA | N12: KEY PIRACICABA | O12: {=IFERROR(_xlfn.XLOOKUP(M12,[1]!Tabela3[[#All],[VENDEDOR]],INDEX([1]!Tabela3[#All],0,MATCH($O$9,[1]!Tabela3[#Headers],0))),0)} -> 0 | P12: =IFERROR(GETPIVOTDATA("[Measures].[Soma de TOTAL 3]",'[1]BASE PYTHON'!$P$32,"[Intervalo 2].[REGIAO]","[Intervalo 2].[REGIAO].&["&N12&"]","[Intervalo 2].[SEMANA]","[Intervalo 2].[SEMANA].&["&RIGHT($O$9,1)&"]"),0) -> 0 | Q12: =Tabela8[[#This Row],[COMPROMISSO]]-Tabela8[[#This Row],[ATINGIDO]] -> 0 | S12: INDAIATUBA | T12: INDAIATUBA | U12: =_xlfn.XLOOKUP(Tabela2[[#This Row],[REFERENCIA]],'[1]BASE PYTHON'!$A$63:$A$79,'[1]BASE PYTHON'!$B$63:$B$79) -> 35 | V12: =IFERROR(VLOOKUP(Tabela2[[#This Row],[REFERENCIA]],'[1]BASE PYTHON'!$K:$N,'[1]BASE PYTHON'!L$1,0),0) -> 0 | W12: =U12-V12 -> 35 | Y12: SJC/VALE | Z12: =_xlfn.XLOOKUP(Tabela17[[#This Row],[VENDEDOR]],[1]!Tabela4[VENDEDOR],[1]!Tabela4[META A]) -> 35 | AA12: =_xlfn.XLOOKUP(Tabela17[[#This Row],[VENDEDOR]],[1]!Tabela4[VENDEDOR],[1]!Tabela4[META B]) -> 30 | AB12: =_xlfn.XLOOKUP(Tabela17[[#This Row],[VENDEDOR]],[1]!Tabela4[VENDEDOR],[1]!Tabela4[META C]) -> 24.5 | AC12: =_xlfn.XLOOKUP(Tabela17[[#This Row],[VENDEDOR]],[1]!Tabela4[VENDEDOR],[1]!Tabela4[META D]) -> 14 | AD12: =IFERROR(_xlfn.XLOOKUP(Y12,'[1]BASE PYTHON'!$K:$K,'[1]BASE PYTHON'!$N:$N,0),0) -> 0 | AE12: {=_xlfn.IFS(AD12>=Z12,"A",AD12>=AA12,"B",AD12>=AB12,"C",AD12>=AC12,"D",TRUE,"NÃO ATINGIDO")} -> NÃO ATINGIDO | AF12: {=_xlfn.IFS(AE12="NÃO ATINGIDO","D",AE12="D","C",AE12="C","B",AE12="B","A",AE12="A","OBJETIVO ALCANÇADO")} -> D | AG12: {=_xlfn.IFS(AF12="D",MAX(AC12-AD12,0),AF12="C",MAX(AB12-AD12,0),AF12="B",MAX(AA12-AD12,0),AF12="A",MAX(Z12-AD12,0),AF12="OBJETIVO ALCANÇADO",0)} -> 14 | AI12: SJC/VALE | AJ12: =_xlfn.XLOOKUP(Tabela817[[#This Row],[VENDEDOR]],[1]!Tabela8[VENDEDOR],[1]!Tabela8[META A]) -> 58000 | AK12: =_xlfn.XLOOKUP(Tabela817[[#This Row],[VENDEDOR]],[1]!Tabela8[VENDEDOR],[1]!Tabela8[META B]) -> 49300 | AL12: =_xlfn.XLOOKUP(Tabela817[[#This Row],[VENDEDOR]],[1]!Tabela8[VENDEDOR],[1]!Tabela8[META C]) -> 40600 | AM12: =_xlfn.XLOOKUP(Tabela817[[#This Row],[VENDEDOR]],[1]!Tabela8[VENDEDOR],[1]!Tabela8[META D]) -> 26100 | AN12: =IFERROR(_xlfn.XLOOKUP(AI12,'[1]BASE PYTHON'!$E:$E,'[1]BASE PYTHON'!$F:$F,0),0) -> 39507.46 | AO12: {=_xlfn.IFS(AN12>=AJ12,"A",AN12>=AK12,"B",AN12>=AL12,"C",AN12>=AM12,"D",TRUE,"NÃO ATINGIDO")} -> D | AP12: {=_xlfn.IFS(AO12="NÃO ATINGIDO","D",AO12="D","C",AO12="C","B",AO12="B","A",AO12="A","OBJETIVO ALCANÇADO")} -> C | AQ12: {=_xlfn.IFS(AP12="D",MAX(AM12-AN12,0),AP12="C",MAX(AL12-AN12,0),AP12="B",MAX(AK12-AN12,0),AP12="A",MAX(AJ12-AN12,0),AP12="OBJETIVO ALCANÇADO",0)} -> 1092.54
A13: INDAIATUBA | B13: INDAIATUBA | C13: =_xlfn.XLOOKUP(Tabela13[[#This Row],[REFERENCIA]],[1]!Tabela2[VENDEDOR],[1]!Tabela2[META A],0) -> 96000 | D13: =_xlfn.XLOOKUP(Tabela13[[#This Row],[REFERENCIA]],'[1]BASE PYTHON'!$E:$E,'[1]BASE PYTHON'!$F:$F,0) -> 62260.59 | E13: =Tabela13[[#This Row],[META A]]-Tabela13[[#This Row],[ATINGIDO]] -> 33739.41 | G13: SBC | H13: SBC | I13: =_xlfn.XLOOKUP(Tabela5[[#This Row],[REFERENCIA]],'[1]BASE PYTHON'!$A$39:$A$55,'[1]BASE PYTHON'!$B$39:$B$55,0) -> 25000 | J13: =_xlfn.XLOOKUP(Tabela5[[#This Row],[REFERENCIA]],'[1]BASE PYTHON'!$H:$H,'[1]BASE PYTHON'!$I:$I,0) -> 215409.79 | K13: =Tabela5[[#This Row],[COMPROMISSO]]-Tabela5[[#This Row],[ATINGIDO]] -> -190409.79 | M13: KEY ZL | N13: KEY ZL | O13: {=IFERROR(_xlfn.XLOOKUP(M13,[1]!Tabela3[[#All],[VENDEDOR]],INDEX([1]!Tabela3[#All],0,MATCH($O$9,[1]!Tabela3[#Headers],0))),0)} -> 0 | P13: =IFERROR(GETPIVOTDATA("[Measures].[Soma de TOTAL 3]",'[1]BASE PYTHON'!$P$32,"[Intervalo 2].[REGIAO]","[Intervalo 2].[REGIAO].&["&N13&"]","[Intervalo 2].[SEMANA]","[Intervalo 2].[SEMANA].&["&RIGHT($O$9,1)&"]"),0) -> 0 | Q13: =Tabela8[[#This Row],[COMPROMISSO]]-Tabela8[[#This Row],[ATINGIDO]] -> 0 | S13: INTERLAGOS | T13: INTERLAGOS | U13: =_xlfn.XLOOKUP(Tabela2[[#This Row],[REFERENCIA]],'[1]BASE PYTHON'!$A$63:$A$79,'[1]BASE PYTHON'!$B$63:$B$79) -> 35 | V13: =IFERROR(VLOOKUP(Tabela2[[#This Row],[REFERENCIA]],'[1]BASE PYTHON'!$K:$N,'[1]BASE PYTHON'!L$1,0),0) -> 0 | W13: =U13-V13 -> 35 | Y13: INDAIATUBA | Z13: =_xlfn.XLOOKUP(Tabela17[[#This Row],[VENDEDOR]],[1]!Tabela4[VENDEDOR],[1]!Tabela4[META A]) -> 35 | AA13: =_xlfn.XLOOKUP(Tabela17[[#This Row],[VENDEDOR]],[1]!Tabela4[VENDEDOR],[1]!Tabela4[META B]) -> 30 | AB13: =_xlfn.XLOOKUP(Tabela17[[#This Row],[VENDEDOR]],[1]!Tabela4[VENDEDOR],[1]!Tabela4[META C]) -> 24.5 | AC13: =_xlfn.XLOOKUP(Tabela17[[#This Row],[VENDEDOR]],[1]!Tabela4[VENDEDOR],[1]!Tabela4[META D]) -> 14 | AD13: =IFERROR(_xlfn.XLOOKUP(Y13,'[1]BASE PYTHON'!$K:$K,'[1]BASE PYTHON'!$N:$N,0),0) -> 0 | AE13: {=_xlfn.IFS(AD13>=Z13,"A",AD13>=AA13,"B",AD13>=AB13,"C",AD13>=AC13,"D",TRUE,"NÃO ATINGIDO")} -> NÃO ATINGIDO | AF13: {=_xlfn.IFS(AE13="NÃO ATINGIDO","D",AE13="D","C",AE13="C","B",AE13="B","A",AE13="A","OBJETIVO ALCANÇADO")} -> D | AG13: {=_xlfn.IFS(AF13="D",MAX(AC13-AD13,0),AF13="C",MAX(AB13-AD13,0),AF13="B",MAX(AA13-AD13,0),AF13="A",MAX(Z13-AD13,0),AF13="OBJETIVO ALCANÇADO",0)} -> 14 | AI13: INDAIATUBA | AJ13: =_xlfn.XLOOKUP(Tabela817[[#This Row],[VENDEDOR]],[1]!Tabela8[VENDEDOR],[1]!Tabela8[META A]) -> 96000 | AK13: =_xlfn.XLOOKUP(Tabela817[[#This Row],[VENDEDOR]],[1]!Tabela8[VENDEDOR],[1]!Tabela8[META B]) -> 81600 | AL13: =_xlfn.XLOOKUP(Tabela817[[#This Row],[VENDEDOR]],[1]!Tabela8[VENDEDOR],[1]!Tabela8[META C]) -> 67200 | AM13: =_xlfn.XLOOKUP(Tabela817[[#This Row],[VENDEDOR]],[1]!Tabela8[VENDEDOR],[1]!Tabela8[META D]) -> 43200 | AN13: =IFERROR(_xlfn.XLOOKUP(AI13,'[1]BASE PYTHON'!$E:$E,'[1]BASE PYTHON'!$F:$F,0),0) -> 62260.59 | AO13: {=_xlfn.IFS(AN13>=AJ13,"A",AN13>=AK13,"B",AN13>=AL13,"C",AN13>=AM13,"D",TRUE,"NÃO ATINGIDO")} -> D | AP13: {=_xlfn.IFS(AO13="NÃO ATINGIDO","D",AO13="D","C",AO13="C","B",AO13="B","A",AO13="A","OBJETIVO ALCANÇADO")} -> C | AQ13: {=_xlfn.IFS(AP13="D",MAX(AM13-AN13,0),AP13="C",MAX(AL13-AN13,0),AP13="B",MAX(AK13-AN13,0),AP13="A",MAX(AJ13-AN13,0),AP13="OBJETIVO ALCANÇADO",0)} -> 4939.41
A14: INTERLAGOS | B14: INTERLAGOS | C14: =_xlfn.XLOOKUP(Tabela13[[#This Row],[REFERENCIA]],[1]!Tabela2[VENDEDOR],[1]!Tabela2[META A],0) -> 281000 | D14: =_xlfn.XLOOKUP(Tabela13[[#This Row],[REFERENCIA]],'[1]BASE PYTHON'!$E:$E,'[1]BASE PYTHON'!$F:$F,0) -> 203747.15 | E14: =Tabela13[[#This Row],[META A]]-Tabela13[[#This Row],[ATINGIDO]] -> 77252.85 | G14: LESTE TATUAPE | H14: TATUAPE | I14: =_xlfn.XLOOKUP(Tabela5[[#This Row],[REFERENCIA]],'[1]BASE PYTHON'!$A$39:$A$55,'[1]BASE PYTHON'!$B$39:$B$55,0) -> 20630 | J14: =_xlfn.XLOOKUP(Tabela5[[#This Row],[REFERENCIA]],'[1]BASE PYTHON'!$H:$H,'[1]BASE PYTHON'!$I:$I,0) -> 122031.33 | K14: =Tabela5[[#This Row],[COMPROMISSO]]-Tabela5[[#This Row],[ATINGIDO]] -> -101401.33 | M14: KEY INTERIOR | N14: KEY INTERIOR | O14: {=IFERROR(_xlfn.XLOOKUP(M14,[1]!Tabela3[[#All],[VENDEDOR]],INDEX([1]!Tabela3[#All],0,MATCH($O$9,[1]!Tabela3[#Headers],0))),0)} -> 0 | P14: =IFERROR(GETPIVOTDATA("[Measures].[Soma de TOTAL 3]",'[1]BASE PYTHON'!$P$32,"[Intervalo 2].[REGIAO]","[Intervalo 2].[REGIAO].&["&N14&"]","[Intervalo 2].[SEMANA]","[Intervalo 2].[SEMANA].&["&RIGHT($O$9,1)&"]"),0) -> 0 | Q14: =Tabela8[[#This Row],[COMPROMISSO]]-Tabela8[[#This Row],[ATINGIDO]] -> 0 | S14: JUNDIAI | T14: JUNDIAI | U14: =_xlfn.XLOOKUP(Tabela2[[#This Row],[REFERENCIA]],'[1]BASE PYTHON'!$A$63:$A$79,'[1]BASE PYTHON'!$B$63:$B$79) -> 35 | V14: =IFERROR(VLOOKUP(Tabela2[[#This Row],[REFERENCIA]],'[1]BASE PYTHON'!$K:$N,'[1]BASE PYTHON'!L$1,0),0) -> 0 | W14: =U14-V14 -> 35 | Y14: CAMPINAS | Z14: =_xlfn.XLOOKUP(Tabela17[[#This Row],[VENDEDOR]],[1]!Tabela4[VENDEDOR],[1]!Tabela4[META A]) -> 35 | AA14: =_xlfn.XLOOKUP(Tabela17[[#This Row],[VENDEDOR]],[1]!Tabela4[VENDEDOR],[1]!Tabela4[META B]) -> 30 | AB14: =_xlfn.XLOOKUP(Tabela17[[#This Row],[VENDEDOR]],[1]!Tabela4[VENDEDOR],[1]!Tabela4[META C]) -> 24.5 | AC14: =_xlfn.XLOOKUP(Tabela17[[#This Row],[VENDEDOR]],[1]!Tabela4[VENDEDOR],[1]!Tabela4[META D]) -> 14 | AD14: =IFERROR(_xlfn.XLOOKUP(Y14,'[1]BASE PYTHON'!$K:$K,'[1]BASE PYTHON'!$N:$N,0),0) -> 0 | AE14: {=_xlfn.IFS(AD14>=Z14,"A",AD14>=AA14,"B",AD14>=AB14,"C",AD14>=AC14,"D",TRUE,"NÃO ATINGIDO")} -> NÃO ATINGIDO | AF14: {=_xlfn.IFS(AE14="NÃO ATINGIDO","D",AE14="D","C",AE14="C","B",AE14="B","A",AE14="A","OBJETIVO ALCANÇADO")} -> D | AG14: {=_xlfn.IFS(AF14="D",MAX(AC14-AD14,0),AF14="C",MAX(AB14-AD14,0),AF14="B",MAX(AA14-AD14,0),AF14="A",MAX(Z14-AD14,0),AF14="OBJETIVO ALCANÇADO",0)} -> 14 | AI14: CAMPINAS | AJ14: =_xlfn.XLOOKUP(Tabela817[[#This Row],[VENDEDOR]],[1]!Tabela8[VENDEDOR],[1]!Tabela8[META A]) -> 70500 | AK14: =_xlfn.XLOOKUP(Tabela817[[#This Row],[VENDEDOR]],[1]!Tabela8[VENDEDOR],[1]!Tabela8[META B]) -> 59925 | AL14: =_xlfn.XLOOKUP(Tabela817[[#This Row],[VENDEDOR]],[1]!Tabela8[VENDEDOR],[1]!Tabela8[META C]) -> 49350 | AM14: =_xlfn.XLOOKUP(Tabela817[[#This Row],[VENDEDOR]],[1]!Tabela8[VENDEDOR],[1]!Tabela8[META D]) -> 31725 | AN14: =IFERROR(_xlfn.XLOOKUP(AI14,'[1]BASE PYTHON'!$E:$E,'[1]BASE PYTHON'!$F:$F,0),0) -> 48786.56 | AO14: {=_xlfn.IFS(AN14>=AJ14,"A",AN14>=AK14,"B",AN14>=AL14,"C",AN14>=AM14,"D",TRUE,"NÃO ATINGIDO")} -> D | AP14: {=_xlfn.IFS(AO14="NÃO ATINGIDO","D",AO14="D","C",AO14="C","B",AO14="B","A",AO14="A","OBJETIVO ALCANÇADO")} -> C | AQ14: {=_xlfn.IFS(AP14="D",MAX(AM14-AN14,0),AP14="C",MAX(AL14-AN14,0),AP14="B",MAX(AK14-AN14,0),AP14="A",MAX(AJ14-AN14,0),AP14="OBJETIVO ALCANÇADO",0)} -> 563.44
A15: JUNDIAI | B15: JUNDIAI | C15: =_xlfn.XLOOKUP(Tabela13[[#This Row],[REFERENCIA]],[1]!Tabela2[VENDEDOR],[1]!Tabela2[META A],0) -> 84000 | D15: =_xlfn.XLOOKUP(Tabela13[[#This Row],[REFERENCIA]],'[1]BASE PYTHON'!$E:$E,'[1]BASE PYTHON'!$F:$F,0) -> 71931.84 | E15: =Tabela13[[#This Row],[META A]]-Tabela13[[#This Row],[ATINGIDO]] -> 12068.16 | G15: CENTRO | H15: CENTRO | I15: =_xlfn.XLOOKUP(Tabela5[[#This Row],[REFERENCIA]],'[1]BASE PYTHON'!$A$39:$A$55,'[1]BASE PYTHON'!$B$39:$B$55,0) -> 32000 | J15: =_xlfn.XLOOKUP(Tabela5[[#This Row],[REFERENCIA]],'[1]BASE PYTHON'!$H:$H,'[1]BASE PYTHON'!$I:$I,0) -> 272619.35 | K15: =Tabela5[[#This Row],[COMPROMISSO]]-Tabela5[[#This Row],[ATINGIDO]] -> -240619.35 | M15: KEY SP | N15: KEY SP | O15: {=IFERROR(_xlfn.XLOOKUP(M15,[1]!Tabela3[[#All],[VENDEDOR]],INDEX([1]!Tabela3[#All],0,MATCH($O$9,[1]!Tabela3[#Headers],0))),0)} -> 0 | P15: =IFERROR(GETPIVOTDATA("[Measures].[Soma de TOTAL 3]",'[1]BASE PYTHON'!$P$32,"[Intervalo 2].[REGIAO]","[Intervalo 2].[REGIAO].&["&N15&"]","[Intervalo 2].[SEMANA]","[Intervalo 2].[SEMANA].&["&RIGHT($O$9,1)&"]"),0) -> 0 | Q15: =Tabela8[[#This Row],[COMPROMISSO]]-Tabela8[[#This Row],[ATINGIDO]] -> 0 | S15: LESTE | T15: LESTE | U15: =_xlfn.XLOOKUP(Tabela2[[#This Row],[REFERENCIA]],'[1]BASE PYTHON'!$A$63:$A$79,'[1]BASE PYTHON'!$B$63:$B$79) -> 0 | V15: =IFERROR(VLOOKUP(Tabela2[[#This Row],[REFERENCIA]],'[1]BASE PYTHON'!$K:$N,'[1]BASE PYTHON'!L$1,0),0) -> 0 | W15: =U15-V15 -> 0 | Y15: JUNDIAI | Z15: =_xlfn.XLOOKUP(Tabela17[[#This Row],[VENDEDOR]],[1]!Tabela4[VENDEDOR],[1]!Tabela4[META A]) -> 35 | AA15: =_xlfn.XLOOKUP(Tabela17[[#This Row],[VENDEDOR]],[1]!Tabela4[VENDEDOR],[1]!Tabela4[META B]) -> 30 | AB15: =_xlfn.XLOOKUP(Tabela17[[#This Row],[VENDEDOR]],[1]!Tabela4[VENDEDOR],[1]!Tabela4[META C]) -> 24.5 | AC15: =_xlfn.XLOOKUP(Tabela17[[#This Row],[VENDEDOR]],[1]!Tabela4[VENDEDOR],[1]!Tabela4[META D]) -> 14 | AD15: =IFERROR(_xlfn.XLOOKUP(Y15,'[1]BASE PYTHON'!$K:$K,'[1]BASE PYTHON'!$N:$N,0),0) -> 0 | AE15: {=_xlfn.IFS(AD15>=Z15,"A",AD15>=AA15,"B",AD15>=AB15,"C",AD15>=AC15,"D",TRUE,"NÃO ATINGIDO")} -> NÃO ATINGIDO | AF15: {=_xlfn.IFS(AE15="NÃO ATINGIDO","D",AE15="D","C",AE15="C","B",AE15="B","A",AE15="A","OBJETIVO ALCANÇADO")} -> D | AG15: {=_xlfn.IFS(AF15="D",MAX(AC15-AD15,0),AF15="C",MAX(AB15-AD15,0),AF15="B",MAX(AA15-AD15,0),AF15="A",MAX(Z15-AD15,0),AF15="OBJETIVO ALCANÇADO",0)} -> 14 | AI15: JUNDIAI | AJ15: =_xlfn.XLOOKUP(Tabela817[[#This Row],[VENDEDOR]],[1]!Tabela8[VENDEDOR],[1]!Tabela8[META A]) -> 84000 | AK15: =_xlfn.XLOOKUP(Tabela817[[#This Row],[VENDEDOR]],[1]!Tabela8[VENDEDOR],[1]!Tabela8[META B]) -> 71400 | AL15: =_xlfn.XLOOKUP(Tabela817[[#This Row],[VENDEDOR]],[1]!Tabela8[VENDEDOR],[1]!Tabela8[META C]) -> 58800 | AM15: =_xlfn.XLOOKUP(Tabela817[[#This Row],[VENDEDOR]],[1]!Tabela8[VENDEDOR],[1]!Tabela8[META D]) -> 37800 | AN15: =IFERROR(_xlfn.XLOOKUP(AI15,'[1]BASE PYTHON'!$E:$E,'[1]BASE PYTHON'!$F:$F,0),0) -> 71931.84 | AO15: {=_xlfn.IFS(AN15>=AJ15,"A",AN15>=AK15,"B",AN15>=AL15,"C",AN15>=AM15,"D",TRUE,"NÃO ATINGIDO")} -> B | AP15: {=_xlfn.IFS(AO15="NÃO ATINGIDO","D",AO15="D","C",AO15="C","B",AO15="B","A",AO15="A","OBJETIVO ALCANÇADO")} -> A | AQ15: {=_xlfn.IFS(AP15="D",MAX(AM15-AN15,0),AP15="C",MAX(AL15-AN15,0),AP15="B",MAX(AK15-AN15,0),AP15="A",MAX(AJ15-AN15,0),AP15="OBJETIVO ALCANÇADO",0)} -> 12068.16
A16: KEY ABC | B16: KEY ABC | C16: =_xlfn.XLOOKUP(Tabela13[[#This Row],[REFERENCIA]],[1]!Tabela2[VENDEDOR],[1]!Tabela2[META A],0) -> 350000 | D16: =_xlfn.XLOOKUP(Tabela13[[#This Row],[REFERENCIA]],'[1]BASE PYTHON'!$E:$E,'[1]BASE PYTHON'!$F:$F,0) -> 194941.35 | E16: =Tabela13[[#This Row],[META A]]-Tabela13[[#This Row],[ATINGIDO]] -> 155058.65 | G16: SANTO ANDRE | H16: SANTO ANDRE | I16: =_xlfn.XLOOKUP(Tabela5[[#This Row],[REFERENCIA]],'[1]BASE PYTHON'!$A$39:$A$55,'[1]BASE PYTHON'!$B$39:$B$55,0) -> 18000 | J16: =_xlfn.XLOOKUP(Tabela5[[#This Row],[REFERENCIA]],'[1]BASE PYTHON'!$H:$H,'[1]BASE PYTHON'!$I:$I,0) -> 135944.55 | K16: =Tabela5[[#This Row],[COMPROMISSO]]-Tabela5[[#This Row],[ATINGIDO]] -> -117944.55 | M16: KEY SJC | N16: KEY SJC | O16: {=IFERROR(_xlfn.XLOOKUP(M16,[1]!Tabela3[[#All],[VENDEDOR]],INDEX([1]!Tabela3[#All],0,MATCH($O$9,[1]!Tabela3[#Headers],0))),0)} -> 0 | P16: =IFERROR(GETPIVOTDATA("[Measures].[Soma de TOTAL 3]",'[1]BASE PYTHON'!$P$32,"[Intervalo 2].[REGIAO]","[Intervalo 2].[REGIAO].&["&N16&"]","[Intervalo 2].[SEMANA]","[Intervalo 2].[SEMANA].&["&RIGHT($O$9,1)&"]"),0) -> 0 | Q16: =Tabela8[[#This Row],[COMPROMISSO]]-Tabela8[[#This Row],[ATINGIDO]] -> 0 | S16: MOGI | T16: MOGI | U16: =_xlfn.XLOOKUP(Tabela2[[#This Row],[REFERENCIA]],'[1]BASE PYTHON'!$A$63:$A$79,'[1]BASE PYTHON'!$B$63:$B$79) -> 35 | V16: =IFERROR(VLOOKUP(Tabela2[[#This Row],[REFERENCIA]],'[1]BASE PYTHON'!$K:$N,'[1]BASE PYTHON'!L$1,0),0) -> 0 | W16: =U16-V16 -> 35 | Y16: PIRITUBA | Z16: =_xlfn.XLOOKUP(Tabela17[[#This Row],[VENDEDOR]],[1]!Tabela4[VENDEDOR],[1]!Tabela4[META A]) -> 35 | AA16: =_xlfn.XLOOKUP(Tabela17[[#This Row],[VENDEDOR]],[1]!Tabela4[VENDEDOR],[1]!Tabela4[META B]) -> 30 | AB16: =_xlfn.XLOOKUP(Tabela17[[#This Row],[VENDEDOR]],[1]!Tabela4[VENDEDOR],[1]!Tabela4[META C]) -> 24.5 | AC16: =_xlfn.XLOOKUP(Tabela17[[#This Row],[VENDEDOR]],[1]!Tabela4[VENDEDOR],[1]!Tabela4[META D]) -> 14 | AD16: =IFERROR(_xlfn.XLOOKUP(Y16,'[1]BASE PYTHON'!$K:$K,'[1]BASE PYTHON'!$N:$N,0),0) -> 0 | AE16: {=_xlfn.IFS(AD16>=Z16,"A",AD16>=AA16,"B",AD16>=AB16,"C",AD16>=AC16,"D",TRUE,"NÃO ATINGIDO")} -> NÃO ATINGIDO | AF16: {=_xlfn.IFS(AE16="NÃO ATINGIDO","D",AE16="D","C",AE16="C","B",AE16="B","A",AE16="A","OBJETIVO ALCANÇADO")} -> D | AG16: {=_xlfn.IFS(AF16="D",MAX(AC16-AD16,0),AF16="C",MAX(AB16-AD16,0),AF16="B",MAX(AA16-AD16,0),AF16="A",MAX(Z16-AD16,0),AF16="OBJETIVO ALCANÇADO",0)} -> 14 | AI16: PIRITUBA | AJ16: =_xlfn.XLOOKUP(Tabela817[[#This Row],[VENDEDOR]],[1]!Tabela8[VENDEDOR],[1]!Tabela8[META A]) -> 142000 | AK16: =_xlfn.XLOOKUP(Tabela817[[#This Row],[VENDEDOR]],[1]!Tabela8[VENDEDOR],[1]!Tabela8[META B]) -> 120700 | AL16: =_xlfn.XLOOKUP(Tabela817[[#This Row],[VENDEDOR]],[1]!Tabela8[VENDEDOR],[1]!Tabela8[META C]) -> 99400 | AM16: =_xlfn.XLOOKUP(Tabela817[[#This Row],[VENDEDOR]],[1]!Tabela8[VENDEDOR],[1]!Tabela8[META D]) -> 63900 | AN16: =IFERROR(_xlfn.XLOOKUP(AI16,'[1]BASE PYTHON'!$E:$E,'[1]BASE PYTHON'!$F:$F,0),0) -> 107918.31 | AO16: {=_xlfn.IFS(AN16>=AJ16,"A",AN16>=AK16,"B",AN16>=AL16,"C",AN16>=AM16,"D",TRUE,"NÃO ATINGIDO")} -> C | AP16: {=_xlfn.IFS(AO16="NÃO ATINGIDO","D",AO16="D","C",AO16="C","B",AO16="B","A",AO16="A","OBJETIVO ALCANÇADO")} -> B | AQ16: {=_xlfn.IFS(AP16="D",MAX(AM16-AN16,0),AP16="C",MAX(AL16-AN16,0),AP16="B",MAX(AK16-AN16,0),AP16="A",MAX(AJ16-AN16,0),AP16="OBJETIVO ALCANÇADO",0)} -> 12781.69
A17: KEY CASA | B17: KEY CASA | C17: =_xlfn.XLOOKUP(Tabela13[[#This Row],[REFERENCIA]],[1]!Tabela2[VENDEDOR],[1]!Tabela2[META A],0) -> 500000 | D17: =_xlfn.XLOOKUP(Tabela13[[#This Row],[REFERENCIA]],'[1]BASE PYTHON'!$E:$E,'[1]BASE PYTHON'!$F:$F,0) -> 350629 | E17: =Tabela13[[#This Row],[META A]]-Tabela13[[#This Row],[ATINGIDO]] -> 149371 | G17: MOGI | H17: MOGI | I17: =_xlfn.XLOOKUP(Tabela5[[#This Row],[REFERENCIA]],'[1]BASE PYTHON'!$A$39:$A$55,'[1]BASE PYTHON'!$B$39:$B$55,0) -> 9790 | J17: =_xlfn.XLOOKUP(Tabela5[[#This Row],[REFERENCIA]],'[1]BASE PYTHON'!$H:$H,'[1]BASE PYTHON'!$I:$I,0) -> 45154.94 | K17: =Tabela5[[#This Row],[COMPROMISSO]]-Tabela5[[#This Row],[ATINGIDO]] -> -35364.94 | M17: KEY CASA | N17: KEY CASA | O17: {=IFERROR(_xlfn.XLOOKUP(M17,[1]!Tabela3[[#All],[VENDEDOR]],INDEX([1]!Tabela3[#All],0,MATCH($O$9,[1]!Tabela3[#Headers],0))),0)} -> 0 | P17: =IFERROR(GETPIVOTDATA("[Measures].[Soma de TOTAL 3]",'[1]BASE PYTHON'!$P$32,"[Intervalo 2].[REGIAO]","[Intervalo 2].[REGIAO].&["&N17&"]","[Intervalo 2].[SEMANA]","[Intervalo 2].[SEMANA].&["&RIGHT($O$9,1)&"]"),0) -> 0 | Q17: =Tabela8[[#This Row],[COMPROMISSO]]-Tabela8[[#This Row],[ATINGIDO]] -> 0 | S17: LESTE MOOCA | T17: MOOCA | U17: =_xlfn.XLOOKUP(Tabela2[[#This Row],[REFERENCIA]],'[1]BASE PYTHON'!$A$63:$A$79,'[1]BASE PYTHON'!$B$63:$B$79) -> 35 | V17: =IFERROR(VLOOKUP(Tabela2[[#This Row],[REFERENCIA]],'[1]BASE PYTHON'!$K:$N,'[1]BASE PYTHON'!L$1,0),0) -> 0 | W17: =U17-V17 -> 35 | Y17: LESTE PENHA | Z17: =_xlfn.XLOOKUP(Tabela17[[#This Row],[VENDEDOR]],[1]!Tabela4[VENDEDOR],[1]!Tabela4[META A]) -> 35 | AA17: =_xlfn.XLOOKUP(Tabela17[[#This Row],[VENDEDOR]],[1]!Tabela4[VENDEDOR],[1]!Tabela4[META B]) -> 30 | AB17: =_xlfn.XLOOKUP(Tabela17[[#This Row],[VENDEDOR]],[1]!Tabela4[VENDEDOR],[1]!Tabela4[META C]) -> 24.5 | AC17: =_xlfn.XLOOKUP(Tabela17[[#This Row],[VENDEDOR]],[1]!Tabela4[VENDEDOR],[1]!Tabela4[META D]) -> 14 | AD17: =IFERROR(_xlfn.XLOOKUP(Y17,'[1]BASE PYTHON'!$K:$K,'[1]BASE PYTHON'!$N:$N,0),0) -> 0 | AE17: {=_xlfn.IFS(AD17>=Z17,"A",AD17>=AA17,"B",AD17>=AB17,"C",AD17>=AC17,"D",TRUE,"NÃO ATINGIDO")} -> NÃO ATINGIDO | AF17: {=_xlfn.IFS(AE17="NÃO ATINGIDO","D",AE17="D","C",AE17="C","B",AE17="B","A",AE17="A","OBJETIVO ALCANÇADO")} -> D | AG17: {=_xlfn.IFS(AF17="D",MAX(AC17-AD17,0),AF17="C",MAX(AB17-AD17,0),AF17="B",MAX(AA17-AD17,0),AF17="A",MAX(Z17-AD17,0),AF17="OBJETIVO ALCANÇADO",0)} -> 14 | AI17: LESTE PENHA | AJ17: =_xlfn.XLOOKUP(Tabela817[[#This Row],[VENDEDOR]],[1]!Tabela8[VENDEDOR],[1]!Tabela8[META A]) -> 169000 | AK17: =_xlfn.XLOOKUP(Tabela817[[#This Row],[VENDEDOR]],[1]!Tabela8[VENDEDOR],[1]!Tabela8[META B]) -> 143650 | AL17: =_xlfn.XLOOKUP(Tabela817[[#This Row],[VENDEDOR]],[1]!Tabela8[VENDEDOR],[1]!Tabela8[META C]) -> 118300 | AM17: =_xlfn.XLOOKUP(Tabela817[[#This Row],[VENDEDOR]],[1]!Tabela8[VENDEDOR],[1]!Tabela8[META D]) -> 76050 | AN17: =IFERROR(_xlfn.XLOOKUP(AI17,'[1]BASE PYTHON'!$E:$E,'[1]BASE PYTHON'!$F:$F,0),0) -> 130217.76 | AO17: {=_xlfn.IFS(AN17>=AJ17,"A",AN17>=AK17,"B",AN17>=AL17,"C",AN17>=AM17,"D",TRUE,"NÃO ATINGIDO")} -> C | AP17: {=_xlfn.IFS(AO17="NÃO ATINGIDO","D",AO17="D","C",AO17="C","B",AO17="B","A",AO17="A","OBJETIVO ALCANÇADO")} -> B | AQ17: {=_xlfn.IFS(AP17="D",MAX(AM17-AN17,0),AP17="C",MAX(AL17-AN17,0),AP17="B",MAX(AK17-AN17,0),AP17="A",MAX(AJ17-AN17,0),AP17="OBJETIVO ALCANÇADO",0)} -> 13432.24
A18: KEY INTERIOR | B18: KEY INTERIOR | C18: =_xlfn.XLOOKUP(Tabela13[[#This Row],[REFERENCIA]],[1]!Tabela2[VENDEDOR],[1]!Tabela2[META A],0) -> 980000 | D18: =_xlfn.XLOOKUP(Tabela13[[#This Row],[REFERENCIA]],'[1]BASE PYTHON'!$E:$E,'[1]BASE PYTHON'!$F:$F,0) -> 560129.58 | E18: =Tabela13[[#This Row],[META A]]-Tabela13[[#This Row],[ATINGIDO]] -> 419870.42 | G18: LESTE | H18: LESTE | I18: =_xlfn.XLOOKUP(Tabela5[[#This Row],[REFERENCIA]],'[1]BASE PYTHON'!$A$39:$A$55,'[1]BASE PYTHON'!$B$39:$B$55,0) -> 0 | J18: =_xlfn.XLOOKUP(Tabela5[[#This Row],[REFERENCIA]],'[1]BASE PYTHON'!$H:$H,'[1]BASE PYTHON'!$I:$I,0) -> 0 | K18: =Tabela5[[#This Row],[COMPROMISSO]]-Tabela5[[#This Row],[ATINGIDO]] -> 0 | S18: NORTE | T18: NORTE | U18: =_xlfn.XLOOKUP(Tabela2[[#This Row],[REFERENCIA]],'[1]BASE PYTHON'!$A$63:$A$79,'[1]BASE PYTHON'!$B$63:$B$79) -> 35 | V18: =IFERROR(VLOOKUP(Tabela2[[#This Row],[REFERENCIA]],'[1]BASE PYTHON'!$K:$N,'[1]BASE PYTHON'!L$1,0),0) -> 0 | W18: =U18-V18 -> 35 | Y18: SBC | Z18: =_xlfn.XLOOKUP(Tabela17[[#This Row],[VENDEDOR]],[1]!Tabela4[VENDEDOR],[1]!Tabela4[META A]) -> 35 | AA18: =_xlfn.XLOOKUP(Tabela17[[#This Row],[VENDEDOR]],[1]!Tabela4[VENDEDOR],[1]!Tabela4[META B]) -> 30 | AB18: =_xlfn.XLOOKUP(Tabela17[[#This Row],[VENDEDOR]],[1]!Tabela4[VENDEDOR],[1]!Tabela4[META C]) -> 24.5 | AC18: =_xlfn.XLOOKUP(Tabela17[[#This Row],[VENDEDOR]],[1]!Tabela4[VENDEDOR],[1]!Tabela4[META D]) -> 14 | AD18: =IFERROR(_xlfn.XLOOKUP(Y18,'[1]BASE PYTHON'!$K:$K,'[1]BASE PYTHON'!$N:$N,0),0) -> 0 | AE18: {=_xlfn.IFS(AD18>=Z18,"A",AD18>=AA18,"B",AD18>=AB18,"C",AD18>=AC18,"D",TRUE,"NÃO ATINGIDO")} -> NÃO ATINGIDO | AF18: {=_xlfn.IFS(AE18="NÃO ATINGIDO","D",AE18="D","C",AE18="C","B",AE18="B","A",AE18="A","OBJETIVO ALCANÇADO")} -> D | AG18: {=_xlfn.IFS(AF18="D",MAX(AC18-AD18,0),AF18="C",MAX(AB18-AD18,0),AF18="B",MAX(AA18-AD18,0),AF18="A",MAX(Z18-AD18,0),AF18="OBJETIVO ALCANÇADO",0)} -> 14 | AI18: SBC | AJ18: =_xlfn.XLOOKUP(Tabela817[[#This Row],[VENDEDOR]],[1]!Tabela8[VENDEDOR],[1]!Tabela8[META A]) -> 270000 | AK18: =_xlfn.XLOOKUP(Tabela817[[#This Row],[VENDEDOR]],[1]!Tabela8[VENDEDOR],[1]!Tabela8[META B]) -> 229500 | AL18: =_xlfn.XLOOKUP(Tabela817[[#This Row],[VENDEDOR]],[1]!Tabela8[VENDEDOR],[1]!Tabela8[META C]) -> 189000 | AM18: =_xlfn.XLOOKUP(Tabela817[[#This Row],[VENDEDOR]],[1]!Tabela8[VENDEDOR],[1]!Tabela8[META D]) -> 121500 | AN18: =IFERROR(_xlfn.XLOOKUP(AI18,'[1]BASE PYTHON'!$E:$E,'[1]BASE PYTHON'!$F:$F,0),0) -> 215409.79 | AO18: {=_xlfn.IFS(AN18>=AJ18,"A",AN18>=AK18,"B",AN18>=AL18,"C",AN18>=AM18,"D",TRUE,"NÃO ATINGIDO")} -> C | AP18: {=_xlfn.IFS(AO18="NÃO ATINGIDO","D",AO18="D","C",AO18="C","B",AO18="B","A",AO18="A","OBJETIVO ALCANÇADO")} -> B | AQ18: {=_xlfn.IFS(AP18="D",MAX(AM18-AN18,0),AP18="C",MAX(AL18-AN18,0),AP18="B",MAX(AK18-AN18,0),AP18="A",MAX(AJ18-AN18,0),AP18="OBJETIVO ALCANÇADO",0)} -> 14090.21
A19: KEY SJC | B19: KEY SJC | C19: =_xlfn.XLOOKUP(Tabela13[[#This Row],[REFERENCIA]],[1]!Tabela2[VENDEDOR],[1]!Tabela2[META A],0) -> 150000 | D19: =_xlfn.XLOOKUP(Tabela13[[#This Row],[REFERENCIA]],'[1]BASE PYTHON'!$E:$E,'[1]BASE PYTHON'!$F:$F,0) -> 45062.2 | E19: =Tabela13[[#This Row],[META A]]-Tabela13[[#This Row],[ATINGIDO]] -> 104937.8 | G19: LESTE MOOCA | H19: MOOCA | I19: =_xlfn.XLOOKUP(Tabela5[[#This Row],[REFERENCIA]],'[1]BASE PYTHON'!$A$39:$A$55,'[1]BASE PYTHON'!$B$39:$B$55,0) -> 17000 | J19: =_xlfn.XLOOKUP(Tabela5[[#This Row],[REFERENCIA]],'[1]BASE PYTHON'!$H:$H,'[1]BASE PYTHON'!$I:$I,0) -> 148229.43 | K19: =Tabela5[[#This Row],[COMPROMISSO]]-Tabela5[[#This Row],[ATINGIDO]] -> -131229.43 | S19: OSASCO | T19: OSASCO | U19: =_xlfn.XLOOKUP(Tabela2[[#This Row],[REFERENCIA]],'[1]BASE PYTHON'!$A$63:$A$79,'[1]BASE PYTHON'!$B$63:$B$79) -> 35 | V19: =IFERROR(VLOOKUP(Tabela2[[#This Row],[REFERENCIA]],'[1]BASE PYTHON'!$K:$N,'[1]BASE PYTHON'!L$1,0),0) -> 0 | W19: =U19-V19 -> 35 | Y19: MOGI | Z19: =_xlfn.XLOOKUP(Tabela17[[#This Row],[VENDEDOR]],[1]!Tabela4[VENDEDOR],[1]!Tabela4[META A]) -> 35 | AA19: =_xlfn.XLOOKUP(Tabela17[[#This Row],[VENDEDOR]],[1]!Tabela4[VENDEDOR],[1]!Tabela4[META B]) -> 30 | AB19: =_xlfn.XLOOKUP(Tabela17[[#This Row],[VENDEDOR]],[1]!Tabela4[VENDEDOR],[1]!Tabela4[META C]) -> 24.5 | AC19: =_xlfn.XLOOKUP(Tabela17[[#This Row],[VENDEDOR]],[1]!Tabela4[VENDEDOR],[1]!Tabela4[META D]) -> 14 | AD19: =IFERROR(_xlfn.XLOOKUP(Y19,'[1]BASE PYTHON'!$K:$K,'[1]BASE PYTHON'!$N:$N,0),0) -> 0 | AE19: {=_xlfn.IFS(AD19>=Z19,"A",AD19>=AA19,"B",AD19>=AB19,"C",AD19>=AC19,"D",TRUE,"NÃO ATINGIDO")} -> NÃO ATINGIDO | AF19: {=_xlfn.IFS(AE19="NÃO ATINGIDO","D",AE19="D","C",AE19="C","B",AE19="B","A",AE19="A","OBJETIVO ALCANÇADO")} -> D | AG19: {=_xlfn.IFS(AF19="D",MAX(AC19-AD19,0),AF19="C",MAX(AB19-AD19,0),AF19="B",MAX(AA19-AD19,0),AF19="A",MAX(Z19-AD19,0),AF19="OBJETIVO ALCANÇADO",0)} -> 14 | AI19: MOGI | AJ19: =_xlfn.XLOOKUP(Tabela817[[#This Row],[VENDEDOR]],[1]!Tabela8[VENDEDOR],[1]!Tabela8[META A]) -> 95500 | AK19: =_xlfn.XLOOKUP(Tabela817[[#This Row],[VENDEDOR]],[1]!Tabela8[VENDEDOR],[1]!Tabela8[META B]) -> 81175 | AL19: =_xlfn.XLOOKUP(Tabela817[[#This Row],[VENDEDOR]],[1]!Tabela8[VENDEDOR],[1]!Tabela8[META C]) -> 66850 | AM19: =_xlfn.XLOOKUP(Tabela817[[#This Row],[VENDEDOR]],[1]!Tabela8[VENDEDOR],[1]!Tabela8[META D]) -> 42975 | AN19: =IFERROR(_xlfn.XLOOKUP(AI19,'[1]BASE PYTHON'!$E:$E,'[1]BASE PYTHON'!$F:$F,0),0) -> 45154.94 | AO19: {=_xlfn.IFS(AN19>=AJ19,"A",AN19>=AK19,"B",AN19>=AL19,"C",AN19>=AM19,"D",TRUE,"NÃO ATINGIDO")} -> D | AP19: {=_xlfn.IFS(AO19="NÃO ATINGIDO","D",AO19="D","C",AO19="C","B",AO19="B","A",AO19="A","OBJETIVO ALCANÇADO")} -> C | AQ19: {=_xlfn.IFS(AP19="D",MAX(AM19-AN19,0),AP19="C",MAX(AL19-AN19,0),AP19="B",MAX(AK19-AN19,0),AP19="A",MAX(AJ19-AN19,0),AP19="OBJETIVO ALCANÇADO",0)} -> 21695.06
A20: KEY SP | B20: KEY SP | C20: =_xlfn.XLOOKUP(Tabela13[[#This Row],[REFERENCIA]],[1]!Tabela2[VENDEDOR],[1]!Tabela2[META A],0) -> 590000 | D20: =_xlfn.XLOOKUP(Tabela13[[#This Row],[REFERENCIA]],'[1]BASE PYTHON'!$E:$E,'[1]BASE PYTHON'!$F:$F,0) -> 288574.26 | E20: =Tabela13[[#This Row],[META A]]-Tabela13[[#This Row],[ATINGIDO]] -> 301425.74 | G20: INTERLAGOS | H20: INTERLAGOS | I20: =_xlfn.XLOOKUP(Tabela5[[#This Row],[REFERENCIA]],'[1]BASE PYTHON'!$A$39:$A$55,'[1]BASE PYTHON'!$B$39:$B$55,0) -> 24730 | J20: =_xlfn.XLOOKUP(Tabela5[[#This Row],[REFERENCIA]],'[1]BASE PYTHON'!$H:$H,'[1]BASE PYTHON'!$I:$I,0) -> 203747.15 | K20: =Tabela5[[#This Row],[COMPROMISSO]]-Tabela5[[#This Row],[ATINGIDO]] -> -179017.15 | N20: SEMANAL | O20: META | P20: REALIZADO | Q20: FALTA | S20: LESTE PENHA | T20: PENHA | U20: =_xlfn.XLOOKUP(Tabela2[[#This Row],[REFERENCIA]],'[1]BASE PYTHON'!$A$63:$A$79,'[1]BASE PYTHON'!$B$63:$B$79) -> 35 | V20: =IFERROR(VLOOKUP(Tabela2[[#This Row],[REFERENCIA]],'[1]BASE PYTHON'!$K:$N,'[1]BASE PYTHON'!L$1,0),0) -> 0 | W20: =U20-V20 -> 35 | Y20: LESTE TATUAPE | Z20: =_xlfn.XLOOKUP(Tabela17[[#This Row],[VENDEDOR]],[1]!Tabela4[VENDEDOR],[1]!Tabela4[META A]) -> 35 | AA20: =_xlfn.XLOOKUP(Tabela17[[#This Row],[VENDEDOR]],[1]!Tabela4[VENDEDOR],[1]!Tabela4[META B]) -> 30 | AB20: =_xlfn.XLOOKUP(Tabela17[[#This Row],[VENDEDOR]],[1]!Tabela4[VENDEDOR],[1]!Tabela4[META C]) -> 24.5 | AC20: =_xlfn.XLOOKUP(Tabela17[[#This Row],[VENDEDOR]],[1]!Tabela4[VENDEDOR],[1]!Tabela4[META D]) -> 14 | AD20: =IFERROR(_xlfn.XLOOKUP(Y20,'[1]BASE PYTHON'!$K:$K,'[1]BASE PYTHON'!$N:$N,0),0) -> 0 | AE20: {=_xlfn.IFS(AD20>=Z20,"A",AD20>=AA20,"B",AD20>=AB20,"C",AD20>=AC20,"D",TRUE,"NÃO ATINGIDO")} -> NÃO ATINGIDO | AF20: {=_xlfn.IFS(AE20="NÃO ATINGIDO","D",AE20="D","C",AE20="C","B",AE20="B","A",AE20="A","OBJETIVO ALCANÇADO")} -> D | AG20: {=_xlfn.IFS(AF20="D",MAX(AC20-AD20,0),AF20="C",MAX(AB20-AD20,0),AF20="B",MAX(AA20-AD20,0),AF20="A",MAX(Z20-AD20,0),AF20="OBJETIVO ALCANÇADO",0)} -> 14 | AI20: LESTE TATUAPE | AJ20: =_xlfn.XLOOKUP(Tabela817[[#This Row],[VENDEDOR]],[1]!Tabela8[VENDEDOR],[1]!Tabela8[META A]) -> 217500 | AK20: =_xlfn.XLOOKUP(Tabela817[[#This Row],[VENDEDOR]],[1]!Tabela8[VENDEDOR],[1]!Tabela8[META B]) -> 184875 | AL20: =_xlfn.XLOOKUP(Tabela817[[#This Row],[VENDEDOR]],[1]!Tabela8[VENDEDOR],[1]!Tabela8[META C]) -> 152250 | AM20: =_xlfn.XLOOKUP(Tabela817[[#This Row],[VENDEDOR]],[1]!Tabela8[VENDEDOR],[1]!Tabela8[META D]) -> 97875 | AN20: =IFERROR(_xlfn.XLOOKUP(AI20,'[1]BASE PYTHON'!$E:$E,'[1]BASE PYTHON'!$F:$F,0),0) -> 122031.33 | AO20: {=_xlfn.IFS(AN20>=AJ20,"A",AN20>=AK20,"B",AN20>=AL20,"C",AN20>=AM20,"D",TRUE,"NÃO ATINGIDO")} -> D | AP20: {=_xlfn.IFS(AO20="NÃO ATINGIDO","D",AO20="D","C",AO20="C","B",AO20="B","A",AO20="A","OBJETIVO ALCANÇADO")} -> C | AQ20: {=_xlfn.IFS(AP20="D",MAX(AM20-AN20,0),AP20="C",MAX(AL20-AN20,0),AP20="B",MAX(AK20-AN20,0),AP20="A",MAX(AJ20-AN20,0),AP20="OBJETIVO ALCANÇADO",0)} -> 30218.67
A21: KEY ZL | B21: KEY ZL | C21: =_xlfn.XLOOKUP(Tabela13[[#This Row],[REFERENCIA]],[1]!Tabela2[VENDEDOR],[1]!Tabela2[META A],0) -> 480000 | D21: =_xlfn.XLOOKUP(Tabela13[[#This Row],[REFERENCIA]],'[1]BASE PYTHON'!$E:$E,'[1]BASE PYTHON'!$F:$F,0) -> 334703.23 | E21: =Tabela13[[#This Row],[META A]]-Tabela13[[#This Row],[ATINGIDO]] -> 145296.77 | G21: JUNDIAI | H21: JUNDIAI | I21: =_xlfn.XLOOKUP(Tabela5[[#This Row],[REFERENCIA]],'[1]BASE PYTHON'!$A$39:$A$55,'[1]BASE PYTHON'!$B$39:$B$55,0) -> 5820 | J21: =_xlfn.XLOOKUP(Tabela5[[#This Row],[REFERENCIA]],'[1]BASE PYTHON'!$H:$H,'[1]BASE PYTHON'!$I:$I,0) -> 71931.84 | K21: =Tabela5[[#This Row],[COMPROMISSO]]-Tabela5[[#This Row],[ATINGIDO]] -> -66111.84 | N21: SEMANA 1 | O21: {=_xlfn.XLOOKUP(Tabela9[[#This Row],[SEMANAL]],[1]!Tabela10[[#All],[Coluna1]],[1]!Tabela10[[#All],[Coluna2]])} -> 290476.19 | P21: =IFERROR(GETPIVOTDATA("[Measures].[Soma de TOTAL 3]",'[1]BASE PYTHON'!$P$32,"[Intervalo 2].[SEMANA]","[Intervalo 2].[SEMANA].&[1]"),0) -> 3483.2 | Q21: =O21-P21 -> 286992.99 | S21: PIRITUBA | T21: PIRITUBA | U21: =_xlfn.XLOOKUP(Tabela2[[#This Row],[REFERENCIA]],'[1]BASE PYTHON'!$A$63:$A$79,'[1]BASE PYTHON'!$B$63:$B$79) -> 35 | V21: =IFERROR(VLOOKUP(Tabela2[[#This Row],[REFERENCIA]],'[1]BASE PYTHON'!$K:$N,'[1]BASE PYTHON'!L$1,0),0) -> 0 | W21: =U21-V21 -> 35 | Y21: Total | Z21: =SUBTOTAL(109,Planilha1!$Z$3:$Z$20) -> 639 | AA21: =SUBTOTAL(109,Planilha1!$AA$3:$AA$20) -> 548 | AB21: =SUBTOTAL(109,Planilha1!$AB$3:$AB$20) -> 448 | AC21: =SUBTOTAL(109,Planilha1!$AC$3:$AC$20) -> 260 | AD21: =SUBTOTAL(109,Planilha1!$AD$3:$AD$20) -> 68 | AG21: =SUBTOTAL(109,Planilha1!$AG$3:$AG$20) -> 235 | AI21: Total | AJ21: =SUBTOTAL(109,Tabela817[META A]) -> 2980000 | AK21: =SUBTOTAL(109,Tabela817[META B]) -> 2533000 | AL21: =SUBTOTAL(109,Tabela817[META C]) -> 2086000 | AM21: =SUBTOTAL(109,Tabela817[META D]) -> 1341000 | AN21: =SUBTOTAL(109,Tabela817[ATINGIDO]) -> 2185106.6 | AQ21: =SUBTOTAL(109,Tabela817[FALTA]) -> 266668.41
A22: LESTE | B22: LESTE | C22: =_xlfn.XLOOKUP(Tabela13[[#This Row],[REFERENCIA]],[1]!Tabela2[VENDEDOR],[1]!Tabela2[META A],0) -> 0 | D22: =_xlfn.XLOOKUP(Tabela13[[#This Row],[REFERENCIA]],'[1]BASE PYTHON'!$E:$E,'[1]BASE PYTHON'!$F:$F,0) -> 0 | E22: =Tabela13[[#This Row],[META A]]-Tabela13[[#This Row],[ATINGIDO]] -> 0 | G22: LESTE PENHA | H22: PENHA | I22: =_xlfn.XLOOKUP(Tabela5[[#This Row],[REFERENCIA]],'[1]BASE PYTHON'!$A$39:$A$55,'[1]BASE PYTHON'!$B$39:$B$55,0) -> 21000 | J22: =_xlfn.XLOOKUP(Tabela5[[#This Row],[REFERENCIA]],'[1]BASE PYTHON'!$H:$H,'[1]BASE PYTHON'!$I:$I,0) -> 130217.76 | K22: =Tabela5[[#This Row],[COMPROMISSO]]-Tabela5[[#This Row],[ATINGIDO]] -> -109217.76 | N22: SEMANA 2 | O22: {=_xlfn.XLOOKUP(Tabela9[[#This Row],[SEMANAL]],[1]!Tabela10[[#All],[Coluna1]],[1]!Tabela10[[#All],[Coluna2]])} -> 726190.48 | P22: =IFERROR(GETPIVOTDATA("[Measures].[Soma de TOTAL 3]",'[1]BASE PYTHON'!$P$32,"[Intervalo 2].[SEMANA]","[Intervalo 2].[SEMANA].&[2]"),0) -> 102026.29 | Q22: =O22-P22 -> 624164.19 | S22: SANTO ANDRE | T22: SANTO ANDRE | U22: =_xlfn.XLOOKUP(Tabela2[[#This Row],[REFERENCIA]],'[1]BASE PYTHON'!$A$63:$A$79,'[1]BASE PYTHON'!$B$63:$B$79) -> 35 | V22: =IFERROR(VLOOKUP(Tabela2[[#This Row],[REFERENCIA]],'[1]BASE PYTHON'!$K:$N,'[1]BASE PYTHON'!L$1,0),0) -> 0 | W22: =U22-V22 -> 35
A23: LESTE MOOCA | B23: MOOCA | C23: =_xlfn.XLOOKUP(Tabela13[[#This Row],[REFERENCIA]],[1]!Tabela2[VENDEDOR],[1]!Tabela2[META A],0) -> 206000 | D23: =_xlfn.XLOOKUP(Tabela13[[#This Row],[REFERENCIA]],'[1]BASE PYTHON'!$E:$E,'[1]BASE PYTHON'!$F:$F,0) -> 148229.43 | E23: =Tabela13[[#This Row],[META A]]-Tabela13[[#This Row],[ATINGIDO]] -> 57770.565 | G23: INDAIATUBA | H23: INDAIATUBA | I23: =_xlfn.XLOOKUP(Tabela5[[#This Row],[REFERENCIA]],'[1]BASE PYTHON'!$A$39:$A$55,'[1]BASE PYTHON'!$B$39:$B$55,0) -> 15850 | J23: =_xlfn.XLOOKUP(Tabela5[[#This Row],[REFERENCIA]],'[1]BASE PYTHON'!$H:$H,'[1]BASE PYTHON'!$I:$I,0) -> 62260.59 | K23: =Tabela5[[#This Row],[COMPROMISSO]]-Tabela5[[#This Row],[ATINGIDO]] -> -46410.59 | N23: SEMANA 3 | O23: {=_xlfn.XLOOKUP(Tabela9[[#This Row],[SEMANAL]],[1]!Tabela10[[#All],[Coluna1]],[1]!Tabela10[[#All],[Coluna2]])} -> 580952.38 | P23: =IFERROR(GETPIVOTDATA("[Measures].[Soma de TOTAL 3]",'[1]BASE PYTHON'!$P$32,"[Intervalo 2].[SEMANA]","[Intervalo 2].[SEMANA].&[3]"),0) -> 190257.24 | Q23: =O23-P23 -> 390695.14 | S23: SBC | T23: SBC | U23: =_xlfn.XLOOKUP(Tabela2[[#This Row],[REFERENCIA]],'[1]BASE PYTHON'!$A$63:$A$79,'[1]BASE PYTHON'!$B$63:$B$79) -> 35 | V23: =IFERROR(VLOOKUP(Tabela2[[#This Row],[REFERENCIA]],'[1]BASE PYTHON'!$K:$N,'[1]BASE PYTHON'!L$1,0),0) -> 0 | W23: =U23-V23 -> 35
A24: LESTE PENHA | B24: PENHA | C24: =_xlfn.XLOOKUP(Tabela13[[#This Row],[REFERENCIA]],[1]!Tabela2[VENDEDOR],[1]!Tabela2[META A],0) -> 169000 | D24: =_xlfn.XLOOKUP(Tabela13[[#This Row],[REFERENCIA]],'[1]BASE PYTHON'!$E:$E,'[1]BASE PYTHON'!$F:$F,0) -> 130217.76 | E24: =Tabela13[[#This Row],[META A]]-Tabela13[[#This Row],[ATINGIDO]] -> 38782.24 | G24: VENDEDOR INTERNO 1 | H24: INTERNO 1 | I24: =_xlfn.XLOOKUP(Tabela5[[#This Row],[REFERENCIA]],'[1]BASE PYTHON'!$A$39:$A$55,'[1]BASE PYTHON'!$B$39:$B$55,0) -> 11080 | J24: =_xlfn.XLOOKUP(Tabela5[[#This Row],[REFERENCIA]],'[1]BASE PYTHON'!$H:$H,'[1]BASE PYTHON'!$I:$I,0) -> 58769.76 | K24: =Tabela5[[#This Row],[COMPROMISSO]]-Tabela5[[#This Row],[ATINGIDO]] -> -47689.76 | N24: SEMANA 4 | O24: {=_xlfn.XLOOKUP(Tabela9[[#This Row],[SEMANAL]],[1]!Tabela10[[#All],[Coluna1]],[1]!Tabela10[[#All],[Coluna2]])} -> 726190.48 | P24: =IFERROR(GETPIVOTDATA("[Measures].[Soma de TOTAL 3]",'[1]BASE PYTHON'!$P$32,"[Intervalo 2].[SEMANA]","[Intervalo 2].[SEMANA].&[4]"),0) -> 54862.27 | Q24: =O24-P24 -> 671328.21 | S24: SJC | T24: SJC | U24: =_xlfn.XLOOKUP(Tabela2[[#This Row],[REFERENCIA]],'[1]BASE PYTHON'!$A$63:$A$79,'[1]BASE PYTHON'!$B$63:$B$79) -> 35 | V24: =IFERROR(VLOOKUP(Tabela2[[#This Row],[REFERENCIA]],'[1]BASE PYTHON'!$K:$N,'[1]BASE PYTHON'!L$1,0),0) -> 0 | W24: =U24-V24 -> 35
A25: LESTE TATUAPE | B25: TATUAPE | C25: =_xlfn.XLOOKUP(Tabela13[[#This Row],[REFERENCIA]],[1]!Tabela2[VENDEDOR],[1]!Tabela2[META A],0) -> 217500 | D25: =_xlfn.XLOOKUP(Tabela13[[#This Row],[REFERENCIA]],'[1]BASE PYTHON'!$E:$E,'[1]BASE PYTHON'!$F:$F,0) -> 122031.33 | E25: =Tabela13[[#This Row],[META A]]-Tabela13[[#This Row],[ATINGIDO]] -> 95468.67 | G25: SJC | H25: SJC | I25: =_xlfn.XLOOKUP(Tabela5[[#This Row],[REFERENCIA]],'[1]BASE PYTHON'!$A$39:$A$55,'[1]BASE PYTHON'!$B$39:$B$55,0) -> 15790 | J25: =_xlfn.XLOOKUP(Tabela5[[#This Row],[REFERENCIA]],'[1]BASE PYTHON'!$H:$H,'[1]BASE PYTHON'!$I:$I,0) -> 59228.23 | K25: =Tabela5[[#This Row],[COMPROMISSO]]-Tabela5[[#This Row],[ATINGIDO]] -> -43438.23 | N25: SEMANA 5 | O25: {=_xlfn.XLOOKUP(Tabela9[[#This Row],[SEMANAL]],[1]!Tabela10[[#All],[Coluna1]],[1]!Tabela10[[#All],[Coluna2]])} -> 726190.48 | P25: =IFERROR(GETPIVOTDATA("[Measures].[Soma de TOTAL 3]",'[1]BASE PYTHON'!$P$32,"[Intervalo 2].[SEMANA]","[Intervalo 2].[SEMANA].&[5]"),0) -> 0 | Q25: =O25-P25 -> 726190.48 | S25: LESTE TATUAPE | T25: TATUAPE | U25: =_xlfn.XLOOKUP(Tabela2[[#This Row],[REFERENCIA]],'[1]BASE PYTHON'!$A$63:$A$79,'[1]BASE PYTHON'!$B$63:$B$79) -> 35 | V25: =IFERROR(VLOOKUP(Tabela2[[#This Row],[REFERENCIA]],'[1]BASE PYTHON'!$K:$N,'[1]BASE PYTHON'!L$1,0),0) -> 0 | W25: =U25-V25 -> 35
A26: MOGI | B26: MOGI | C26: =_xlfn.XLOOKUP(Tabela13[[#This Row],[REFERENCIA]],[1]!Tabela2[VENDEDOR],[1]!Tabela2[META A],0) -> 95500 | D26: =_xlfn.XLOOKUP(Tabela13[[#This Row],[REFERENCIA]],'[1]BASE PYTHON'!$E:$E,'[1]BASE PYTHON'!$F:$F,0) -> 45154.94 | E26: =Tabela13[[#This Row],[META A]]-Tabela13[[#This Row],[ATINGIDO]] -> 50345.06 | G26: SJC/VALE | H26: VALE | I26: =_xlfn.XLOOKUP(Tabela5[[#This Row],[REFERENCIA]],'[1]BASE PYTHON'!$A$39:$A$55,'[1]BASE PYTHON'!$B$39:$B$55,0) -> 10060 | J26: =_xlfn.XLOOKUP(Tabela5[[#This Row],[REFERENCIA]],'[1]BASE PYTHON'!$H:$H,'[1]BASE PYTHON'!$I:$I,0) -> 39507.46 | K26: =Tabela5[[#This Row],[COMPROMISSO]]-Tabela5[[#This Row],[ATINGIDO]] -> -29447.46 | S26: SJC/VALE | T26: VALE | U26: =_xlfn.XLOOKUP(Tabela2[[#This Row],[REFERENCIA]],'[1]BASE PYTHON'!$A$63:$A$79,'[1]BASE PYTHON'!$B$63:$B$79) -> 35 | V26: =IFERROR(VLOOKUP(Tabela2[[#This Row],[REFERENCIA]],'[1]BASE PYTHON'!$K:$N,'[1]BASE PYTHON'!L$1,0),0) -> 0 | W26: =U26-V26 -> 35
A27: NORTE | B27: NORTE | C27: =_xlfn.XLOOKUP(Tabela13[[#This Row],[REFERENCIA]],[1]!Tabela2[VENDEDOR],[1]!Tabela2[META A],0) -> 272000 | D27: =_xlfn.XLOOKUP(Tabela13[[#This Row],[REFERENCIA]],'[1]BASE PYTHON'!$E:$E,'[1]BASE PYTHON'!$F:$F,0) -> 211937.02 | E27: =Tabela13[[#This Row],[META A]]-Tabela13[[#This Row],[ATINGIDO]] -> 60062.98 | G27: CAMPINAS | H27: CAMPINAS | I27: =_xlfn.XLOOKUP(Tabela5[[#This Row],[REFERENCIA]],'[1]BASE PYTHON'!$A$39:$A$55,'[1]BASE PYTHON'!$B$39:$B$55,0) -> 5870 | J27: =_xlfn.XLOOKUP(Tabela5[[#This Row],[REFERENCIA]],'[1]BASE PYTHON'!$H:$H,'[1]BASE PYTHON'!$I:$I,0) -> 48786.56 | K27: =Tabela5[[#This Row],[COMPROMISSO]]-Tabela5[[#This Row],[ATINGIDO]] -> -42916.56
A28: OSASCO | B28: OSASCO | C28: =_xlfn.XLOOKUP(Tabela13[[#This Row],[REFERENCIA]],[1]!Tabela2[VENDEDOR],[1]!Tabela2[META A],0) -> 331500 | D28: =_xlfn.XLOOKUP(Tabela13[[#This Row],[REFERENCIA]],'[1]BASE PYTHON'!$E:$E,'[1]BASE PYTHON'!$F:$F,0) -> 251412.52 | E28: =Tabela13[[#This Row],[META A]]-Tabela13[[#This Row],[ATINGIDO]] -> 80087.485
A29: KEY PIRACICABA | B29: KEY PIRACICABA | C29: =_xlfn.XLOOKUP(Tabela13[[#This Row],[REFERENCIA]],[1]!Tabela2[VENDEDOR],[1]!Tabela2[META A],0) -> 0 | D29: =_xlfn.XLOOKUP(Tabela13[[#This Row],[REFERENCIA]],'[1]BASE PYTHON'!$E:$E,'[1]BASE PYTHON'!$F:$F,0) -> 0 | E29: =Tabela13[[#This Row],[META A]]-Tabela13[[#This Row],[ATINGIDO]] -> 0 | T29: SEMANAL | U29: META | V29: REALIZADO | W29: FALTA
A30: PIRITUBA | B30: PIRITUBA | C30: =_xlfn.XLOOKUP(Tabela13[[#This Row],[REFERENCIA]],[1]!Tabela2[VENDEDOR],[1]!Tabela2[META A],0) -> 142000 | D30: =_xlfn.XLOOKUP(Tabela13[[#This Row],[REFERENCIA]],'[1]BASE PYTHON'!$E:$E,'[1]BASE PYTHON'!$F:$F,0) -> 107918.31 | E30: =Tabela13[[#This Row],[META A]]-Tabela13[[#This Row],[ATINGIDO]] -> 34081.69 | H30: SEMANAL | I30: META | J30: REALIZADO | K30: FALTA | T30: SEMANA 1 | U30: {=_xlfn.XLOOKUP(Tabela12[[#This Row],[SEMANAL]],[1]!Tabela11[[#All],[Coluna1]],[1]!Tabela11[[#All],[Coluna2]])} -> 53.333333 | V30: =IFERROR(GETPIVOTDATA("[Measures].[Contagem Distinta de COD_CLIENTE 2]",'[1]BASE PYTHON'!$P$83,"[Intervalo 3].[SEMANAL]","[Intervalo 3].[SEMANAL].&[1]"),0) -> 21 | W30: =U30-V30 -> 32.333333
